Workbook

Sheet Összefoglaló
A1: babylon-grow.eu – Cserép, tálca főkategória kulcsszókutatás (Google Ads Kulcsszótervező, HU, magyar, 12 hó átlag)
A2: Forrás: Babylon Adwords fiók (867-850-6485) Kulcsszótervező (Windsor.ai-on át), lekérdezve: 2026-10-12 és 2026-10-14. Hely: Magyarország, nyelv: magyar, hálózat: Google Keresés. A számok kerekített lépcsős havi átlagok.
A4: Kategória (menünév) | B4: Fő kulcsszó | C4: Fő kulcsszó havi | D4: Klaszter összesen (érdemes = Igen) | E4: Kötődés a webshophoz | F4: Érdemes rá kategória? | G4: Felhasználási terület | H4: Javasolt hely az új fában
A5: Virágcserép | B5: virágcserép | C5: =SUMIFS('Összes kulcsszó'!$E:$E,'Összes kulcsszó'!$A:$A,A5,'Összes kulcsszó'!$C:$C,B5) | D5: =SUMIFS('Összes kulcsszó'!$E:$E,'Összes kulcsszó'!$A:$A,A5,'Összes kulcsszó'!$G:$G,"Igen") | E5: Szoros | F5: Igen | G5: Termesztő cserép – műanyag, kerek, literes méretek | H5: 2. szint – „Virágcserép” (sandbox-név marad); H1 / SEO title: „Műanyag virágcserép”; szűrők: térfogat (liter), átmérő, forma
A6: Nagy virágcserép | B6: nagy virágcserép | C6: =SUMIFS('Összes kulcsszó'!$E:$E,'Összes kulcsszó'!$A:$A,A6,'Összes kulcsszó'!$C:$C,B6) | D6: =SUMIFS('Összes kulcsszó'!$E:$E,'Összes kulcsszó'!$A:$A,A6,'Összes kulcsszó'!$G:$G,"Igen") | E6: Szoros | F6: Igen | G6: Nagy térfogatú cserép – 20–100 literes termesztés, kültér | H6: 3. szint a Virágcserép alatt – csak ha legalább 3–4 nagy (kb. 20 l feletti) cserép van a kínálatban; különben a Virágcserép másodlagos kulcsszava
A7: Szögletes cserép | B7: szögletes virágcserép | C7: =SUMIFS('Összes kulcsszó'!$E:$E,'Összes kulcsszó'!$A:$A,A7,'Összes kulcsszó'!$C:$C,B7) | D7: =SUMIFS('Összes kulcsszó'!$E:$E,'Összes kulcsszó'!$A:$A,A7,'Összes kulcsszó'!$G:$G,"Igen") | E7: Szoros | F7: Igen | G7: Helytakarékos termesztés sátorban / polcon | H7: Szűrő a Virágcserép kategóriában (forma: kerek / szögletes) – önálló kategóriának kevés
A8: Air-Pot cserép | B8: airpot | C8: =SUMIFS('Összes kulcsszó'!$E:$E,'Összes kulcsszó'!$A:$A,A8,'Összes kulcsszó'!$C:$C,B8) | D8: =SUMIFS('Összes kulcsszó'!$E:$E,'Összes kulcsszó'!$A:$A,A8,'Összes kulcsszó'!$G:$G,"Igen") | E8: Szoros | F8: Igen | G8: Gyökérlégzés, gyökérmetszés – termesztés konténerben | H8: 2. szint – a „Speciális cserép, szövetcserép” helyett vagy alatta; a menünévben a márkanév legyen
A9: Szövetcserép, ültetőzsák | B9: ültetőzsák | C9: =SUMIFS('Összes kulcsszó'!$E:$E,'Összes kulcsszó'!$A:$A,A9,'Összes kulcsszó'!$C:$C,B9) | D9: =SUMIFS('Összes kulcsszó'!$E:$E,'Összes kulcsszó'!$A:$A,A9,'Összes kulcsszó'!$G:$G,"Igen") | E9: Szoros | F9: Igen | G9: Szövet / textil / filc cserép, ültető- és termesztőzsák | H9: 2. szint – a „Speciális cserép, szövetcserép” utódja; menünév: „Szövetcserép, ültetőzsák”
A10: Cserépalátét | B10: cserépalátét | C10: =SUMIFS('Összes kulcsszó'!$E:$E,'Összes kulcsszó'!$A:$A,A10,'Összes kulcsszó'!$C:$C,B10) | D10: =SUMIFS('Összes kulcsszó'!$E:$E,'Összes kulcsszó'!$A:$A,A10,'Összes kulcsszó'!$G:$G,"Igen") | E10: Szoros | F10: Igen | G10: Cserép alá – vízfelfogás, gurulós alátét | H10: 2. szint – a „Tálca, alátét” kettébontásával; az „alátét” szó önmagában csavaralátét
A11: Műanyag tálca, árapály asztal | B11: nagyméretű műanyag tálca | C11: =SUMIFS('Összes kulcsszó'!$E:$E,'Összes kulcsszó'!$A:$A,A11,'Összes kulcsszó'!$C:$C,B11) | D11: =SUMIFS('Összes kulcsszó'!$E:$E,'Összes kulcsszó'!$A:$A,A11,'Összes kulcsszó'!$G:$G,"Igen") | E11: Laza | F11: Igen | G11: Gyűjtőtálca termesztősátorba, árapály (ebb & flow) rendszer | H11: 2. szint – a „Tálca, alátét” kettébontásával
A13: Jelmagyarázat
A14: Szoros kötődés · érdemes: Igen
A15: Laza kötődés · érdemes: Igen
A16: Laza kötődés · érdemes: Nem
A17: Nincs (áruházi / nem vásárlási szándék) kötődés · érdemes: Nem – kizárandó
A19: Termékek: 1999 termék a Google Shopping-feedből (2024-10 – 2026-10); ebből a cserép–tálca témájú termékek besorolva – a Termékkínálat lapon és a kategórialapok alján.
A20: Megjegyzés: a klaszter-összeg átfedéseket tartalmazhat (pl. elírt és ékezet nélküli változatok, amelyeket a Google külön sorban is mutat).
A21: Fő megállapítás: a virágcserép (2400) és a nagy virágcserép (480) viszi az ágat; a sandbox két gyűjtőnevére („Speciális cserép”, „Tálca, alátét”) nincs vagy félrevezető a keresés – javasolt a kettébontásuk (Kategóriaszerkezet-ajánlás lap).
A22: Az éles oldal jelenlegi kategóriáit nem vettük figyelembe; a javaslat a sandbox-tervezetre és a kulcsszóadatra épül.
A23: A „szaporító tálca” / „palántanevelő tálca” céloldala a Palántanevelő ág, a „mikrozöld tálca” a Mikrozöld termesztésé – itt csak említés.

Sheet Kategóriaszerkezet-ajánlás
A1: Kategóriaszerkezet-ajánlás – Cserép, tálca (termékkínálat + kulcsszóadat alapján)
A2: Az éles oldal jelenlegi kategóriáit nem vettük figyelembe. Kiindulás: a sandbox-tervezet, a Google Shopping-feed termékei (1999 db) és a Kulcsszótervező adatai. Termékszám = elsődleges + másodlagos hozzárendelés.
A4: Szint | B4: Javasolt kategórianév (menünév) | C4: Szülőkategória | D4: Fő kulcsszó | E4: Fő kulcsszó havi | F4: Klaszter összesen (érdemes = Igen) | G4: Kulcsszó-kötődés | H4: Termékek száma | I4: Típus | J4: Indoklás
A5: 1 | B5: Cserép, tálca | C5: – | D5: virágcserép | E5: 2400 | G5: Erősen kapcsolódik | H5: 142 | I5: Főkategória | J5: A főkategória-névre nincs saját keresés („cserép” = tetőcserép); a H1 a virágcserép / cserépalátét / tálca szavakra épüljön.
A6: 2 | B6: Virágcserép | C6: Cserép, tálca | D6: virágcserép | E6: 2400 | F6: =SUMIFS('Összes kulcsszó'!$E:$E,'Összes kulcsszó'!$A:$A,"Virágcserép",'Összes kulcsszó'!$G:$G,"Igen") | G6: Erősen kapcsolódik | H6: 57 | I6: Önálló kategória | J6: A főkategória legerősebb klasztere (virágcserép 2400, műanyag virágcserép 590, műanyag cserép 480). Térfogat (liter) és forma szűrővel.
A7: 3 | B7: Nagy virágcserép | C7: Virágcserép | D7: nagy virágcserép | E7: 480 | F7: =SUMIFS('Összes kulcsszó'!$E:$E,'Összes kulcsszó'!$A:$A,"Nagy virágcserép",'Összes kulcsszó'!$G:$G,"Igen") | G7: Erősen kapcsolódik | H7: 25 | I7: Önálló kategória | J7: Erős saját klaszter (480 + 320 + 260), és sok 20 literes feletti cserép / konténer van a kínálatban – önálló 3. szint.
A8: 3 | B8: Szögletes cserép | C8: Virágcserép | D8: szögletes virágcserép | E8: 90 | F8: =SUMIFS('Összes kulcsszó'!$E:$E,'Összes kulcsszó'!$A:$A,"Szögletes cserép",'Összes kulcsszó'!$G:$G,"Igen") | G8: Erősen kapcsolódik | H8: 24 | I8: Szűrő | J8: Kis keresési volumen (90 + 70 + 40), de sok szögletes termék van – forma-szűrő; ha a sandbox engedi, 3. szint is lehet.
A9: 2 | B9: Air-Pot cserép | C9: Cserép, tálca | D9: airpot | E9: 140 | F9: =SUMIFS('Összes kulcsszó'!$E:$E,'Összes kulcsszó'!$A:$A,"Air-Pot cserép",'Összes kulcsszó'!$G:$G,"Igen") | G9: Erősen kapcsolódik | H9: 13 | I9: Önálló kategória | J9: A sandbox „Speciális cserép” helyett: a márkanévre van keresés (airpot 140, air pot 90), a „légmetsző cserép”-re nincs.
A10: 2 | B10: Szövetcserép, ültetőzsák | C10: Cserép, tálca | D10: ültetőzsák | E10: 90 | F10: =SUMIFS('Összes kulcsszó'!$E:$E,'Összes kulcsszó'!$A:$A,"Szövetcserép, ültetőzsák",'Összes kulcsszó'!$G:$G,"Igen") | G10: Erősen kapcsolódik | H10: 28 | I10: Önálló kategória | J10: Az „ültetőzsák” (90 + 50) viszi; a szövet / textil cserép, smart pot, grow bag egyenként 20.
A11: 2 | B11: Cserépalátét | C11: Cserép, tálca | D11: cserépalátét | E11: 260 | F11: =SUMIFS('Összes kulcsszó'!$E:$E,'Összes kulcsszó'!$A:$A,"Cserépalátét",'Összes kulcsszó'!$G:$G,"Igen") | G11: Erősen kapcsolódik | H11: 40 | I11: Önálló kategória | J11: A sandbox „Tálca, alátét” kettébontása: a cserépalátét-klaszter önmagában erős (260 + 260 + 140 + 140 + 110).
A12: 2 | B12: Műanyag tálca, árapály asztal | C12: Cserép, tálca | D12: nagyméretű műanyag tálca | E12: 140 | F12: =SUMIFS('Összes kulcsszó'!$E:$E,'Összes kulcsszó'!$A:$A,"Műanyag tálca, árapály asztal",'Összes kulcsszó'!$G:$G,"Igen") | G12: Lazán kapcsolódik | H12: 36 | I12: Önálló kategória | J12: Gyűjtőtálca sátorba és árapály rendszer (ebb and flow 70, árapály asztal 50). A „gyűjtőtálca” névre nincs keresés.
A14: Ami NE legyen önálló kategória
A15: Téma | B15: Kulcsszó | C15: Havi keresés | D15: Javaslat
A16: Speciális cserép (sandbox-név) | B16: szövetcserép | C16: 10 | D16: A „speciális cserép” névre nincs mérhető keresés – helyette Air-Pot és Szövetcserép, ültetőzsák.
A17: Literes méretek | B17: 20 literes cserép | C17: 50 | D17: Szűrő (térfogat) a Virágcserép kategóriában, nem kategória.
A18: Szaporító / palántanevelő tálca | B18: szaporító tálca | C18: 320 | D18: A Palántanevelő / mini üvegház ág céloldala – itt csak említés (kannibalizáció).
A19: Mikrozöld tálca | B19: mikrozöld tálca | C19: 70 | D19: A Mikrozöld termesztés főkategóriáé.
A20: Csepptálca, kármentő | B20: kármentő tálca | C20: 480 | D20: Klíma / ipari keresés – nem célozni.
A21: Önöntöző cserép | B21: önöntöző cserép | C21: 90 | D21: Van keresés (90), de nincs ilyen termék – csak kínálatbővítés esetén.
A22: Palántázó kiscserép (4–12 cm), tőzegcserép | B22: palántanevelő cserép | C22: 140 | D22: A Palántanevelő ág kategóriája – itt legfeljebb másodlagos hozzárendelés.

Sheet Termékkínálat
A1: Termékkínálat – termék–kategória hozzárendelés
A2: Forrás: a Babylon Google Ads fiók Shopping-termékadatai (termékkód = Shopping item ID, terméknév = feed-cím), 2024-10-01 – 2026-10-14, összesen 1999 termék. A Shoprenter API és az éles oldal a felhőből továbbra sem érhető el.
A3: Figyelem: ez a Google-ben hirdetett termékkör, nem feltétlenül a teljes katalógus – a feedből kimaradt vagy soha nem hirdetett termékek itt nem szerepelnek. A gyártó és a gyűjtőtermék (GYUJTO…) adat a feedben nem érhető el.
A4: A „Más főkategória” sorok cserép / tálca jellegű termékek, amelyeknek a helye egy másik főkategóriában van (Palántanevelő, Mikrozöld, Hidro, Közegek, Esővízgyűjtő).
A5: A lapon a teljes termékkínálat szerepel (1999 termék): elöl a Cserép, tálca kategóriákba sorolt termékek (Erős, Laza), majd a más főkategóriába való cserép- / tálcajellegű termékek, végül „Nem tartozik ide” jelöléssel az összes többi. Az Illeszkedés oszlopra szűrve csak a besoroltak láthatók.
A7: Termékkód | B7: Terméknév | C7: Elsődleges javasolt kategória | D7: További kategóriák | E7: Illeszkedés | F7: Utoljára a Google Shopping-feedben | G7: Megjegyzés
A8: GRO1890 | B8: Air-Pot klón 1 literes perforált, légáteresztő műanyag edény erős gyökérzethez | C8: Air-Pot cserép | E8: Erős | F8: az elmúlt 30 napban | G8: Air-Pot (klón) perforált cserép
A9: GRO1891 | B9: Air-Pot klón 3 literes perforált, légáteresztő műanyag edény erős gyökérzethez | C9: Air-Pot cserép | E9: Erős | F9: az elmúlt 30 napban | G9: Air-Pot (klón) perforált cserép
A10: GRO1892 | B10: Air-Pot klón 6 literes perforált, légáteresztő műanyag edény erős gyökérzethez | C10: Air-Pot cserép | E10: Erős | F10: az elmúlt 30 napban | G10: Air-Pot (klón) perforált cserép
A11: GRO1893 | B11: Air-Pot klón 10 literes perforált, légáteresztő műanyag edény erős gyökérzethez | C11: Air-Pot cserép | E11: Erős | F11: az elmúlt 30 napban | G11: Air-Pot (klón) perforált cserép
A12: GRO1894 | B12: Air-Pot klón 15 literes perforált, légáteresztő műanyag edény erős gyökérzethez | C12: Air-Pot cserép | E12: Erős | F12: az elmúlt 30 napban | G12: Air-Pot (klón) perforált cserép
A13: GRO1895 | B13: Air-Pot klón 25 literes perforált, légáteresztő műanyag edény erős gyökérzethez | C13: Air-Pot cserép | E13: Erős | F13: az elmúlt 30 napban | G13: Air-Pot (klón) perforált cserép
A14: GRO2571 | B14: Air-Pot klón 50 literes perforált, légáteresztő műanyag edény erős gyökérzethez | C14: Air-Pot cserép | D14: Nagy virágcserép | E14: Erős | F14: az elmúlt 30 napban | G14: Air-Pot klón 50 l
A15: GRO3346 | B15: Air-pot cserép 3 liter | C15: Air-Pot cserép | E15: Erős | F15: az elmúlt 30 napban | G15: Air-Pot (klón) perforált cserép
A16: GRO3525 | B16: Air-pot cserép 5 liter | C16: Air-Pot cserép | E16: Erős | F16: az elmúlt 30 napban | G16: Air-Pot (klón) perforált cserép
A17: GRO3526 | B17: Air-pot cserép 9 liter | C17: Air-Pot cserép | E17: Erős | F17: az elmúlt 30 napban | G17: Air-Pot (klón) perforált cserép
A18: GRO1049 | B18: Szögletes műanyag virágcserép alátét 16 x 16 cm | C18: Cserépalátét | E18: Erős | F18: az elmúlt 30 napban | G18: Szögletes cserépalátét
A19: GRO1184 | B19: Szögletes műanyag virágcserép alátét 13,5 x 13,5 cm | C19: Cserépalátét | E19: Erős | F19: az elmúlt 30 napban | G19: Szögletes cserépalátét
A20: GRO1185 | B20: Szögletes műanyag virágcserép alátét 14 x 14 cm | C20: Cserépalátét | E20: Erős | F20: az elmúlt 30 napban | G20: Szögletes cserépalátét
A21: GRO1190 | B21: Szögletes műanyag virágcserép alátét 24 x 24 cm | C21: Cserépalátét | E21: Erős | F21: az elmúlt 30 napban | G21: Szögletes cserépalátét
A22: GRO1262 | B22: Szögletes műanyag virágcserép alátét 25 x 25 cm | C22: Cserépalátét | E22: Erős | F22: az elmúlt 30 napban | G22: Szögletes cserépalátét
A23: GRO1813 | B23: Szögletes műanyag virágcserép alátét 10,5 x 10,5 cm | C23: Cserépalátét | E23: Erős | F23: az elmúlt 30 napban | G23: Szögletes cserépalátét
A24: GRO1814 | B24: Szögletes műanyag virágcserép alátét 19.5x19.5 | C24: Cserépalátét | E24: Erős | F24: az elmúlt 30 napban | G24: Szögletes cserépalátét
A25: GRO2105 | B25: Szögletes műanyag virágcserép alátét 17.5x17.5 | C25: Cserépalátét | E25: Erős | F25: az elmúlt 6 hónapban | G25: Szögletes cserépalátét
A26: GRO2106 | B26: Szögletes műanyag virágcserép alátét 20,5 x 20,5 cm | C26: Cserépalátét | E26: Erős | F26: az elmúlt 30 napban | G26: Szögletes cserépalátét
A27: GRO3717 | B27: Kerek műanyag virágcserép alátét | C27: Cserépalátét | E27: Erős | F27: az elmúlt 30 napban | G27: Kerek cserépalátét
A28: GRO4408 | B28: Cserépalátét univerzális tálca 72x50 cm | C28: Cserépalátét | D28: Műanyag tálca, árapály asztal | E28: Erős | F28: az elmúlt 6 hónapban | G28: Univerzális alátéttálca
A29: GRO4654 | B29: Kerek cserépalátét fekete, 18 cm átmérővel | C29: Cserépalátét | E29: Erős | F29: az elmúlt 30 napban | G29: Kerek cserépalátét
A30: GRO4655 | B30: Kerek cserépalátét, fekete, 20 cm átmérő | C30: Cserépalátét | E30: Erős | F30: az elmúlt 30 napban | G30: Kerek cserépalátét
A31: GRO4656 | B31: Kerek cserépalátét, fekete, 30 cm átmérő | C31: Cserépalátét | E31: Erős | F31: az elmúlt 30 napban | G31: Kerek cserépalátét
A32: GRO4659 | B32: Fekete kerek cserépalátét, 35 cm átmérő | C32: Cserépalátét | E32: Erős | F32: az elmúlt 30 napban | G32: Kerek cserépalátét
A33: GRO0054 | B33: Dán tálca apály-dagály alátét 106 x 33 cm árasztásos rendszerhez | C33: Műanyag tálca, árapály asztal | E33: Erős | F33: az elmúlt 30 napban | G33: Dán tálca – apály-dagály (árapály) rendszer
A34: GRO0056 | B34: Dán tálca apály-dagály alátét 106 x 102 cm árasztásos rendszerhez | C34: Műanyag tálca, árapály asztal | E34: Erős | F34: az elmúlt 30 napban | G34: Dán tálca – apály-dagály (árapály) rendszer
A35: GRO0057 | B35: Dán tálca apály-dagály alátét 106 x 202 cm árasztásos rendszerhez | C35: Műanyag tálca, árapály asztal | E35: Erős | F35: az elmúlt 30 napban | G35: Dán tálca – apály-dagály (árapály) rendszer
A36: GRO1417 | B36: Dán tálca apály-dagály alátét 106 x 63 cm árasztásos rendszerhez | C36: Műanyag tálca, árapály asztal | E36: Erős | F36: az elmúlt 30 napban | G36: Dán tálca – apály-dagály (árapály) rendszer
A37: GRO1462 | B37: Garland tálca (12 cm magas) M | C37: Műanyag tálca, árapály asztal | D37: Cserépalátét | E37: Erős | F37: az elmúlt 6 hónapban | G37: Garland tálca (5–15 cm perem)
A38: GRO1463 | B38: Garland Titan tálca 100 x 55 x 15 cm, 65 literes, újrahasznosított polipropilén | C38: Műanyag tálca, árapály asztal | D38: Cserépalátét | E38: Erős | F38: az elmúlt 30 napban | G38: Garland tálca (5–15 cm perem)
A39: GRO1906 | B39: Garland Square négyzetes tálca 59 x 59 x 7 cm (M), fröccsöntött polipropilén | C39: Műanyag tálca, árapály asztal | D39: Cserépalátét | E39: Erős | F39: az elmúlt 30 napban | G39: Garland tálca (5–15 cm perem)
A40: GRO1907 | B40: Garland Giant tálca 110 x 55 x 5 cm, hosszúkás, fröccsöntött polipropilén | C40: Műanyag tálca, árapály asztal | D40: Cserépalátét | E40: Erős | F40: az elmúlt 30 napban | G40: Garland tálca (5–15 cm perem)
A41: GRO1908 | B41: Garland tálca (12 cm magas) L | C41: Műanyag tálca, árapály asztal | D41: Cserépalátét | E41: Erős | F41: az elmúlt 30 napban | G41: Garland tálca (5–15 cm perem)
...

Sheet Bővítés – rokon területek
A1: Rokon, cserepekhez kapcsolódó területek (Kulcsszótervező, HU, 12 hó átlag)
A2: Más szándékú vagy más főkategóriába tartozó témák – csak ha van hozzá termék.
A4: Terület | B4: Javaslat | C4: Releváns keresés (Szoros+Laza)
A5: Önöntöző cserép | B5: Nincs önöntöző cserép a kínálatban (csak egy víztartályos alátét) – kategória csak kínálatbővítés esetén | C5: =SUMIFS(C13:C34,A13:A34,A5,E13:E34,"<>Nem")
A6: Műanyag vödör | B6: Csak ha van vödör (pl. DWC / hidro vödör) – akkor a Hidro ágba vagy szűrőként | C6: =SUMIFS(C13:C34,A13:A34,A6,E13:E34,"<>Nem")
A7: Hidrokultúrás cserép, hálós kosár | B7: A Hidro főkategóriába (ha van); innen kereszt-link | C7: =SUMIFS(C13:C34,A13:A34,A7,E13:E34,"<>Nem")
A8: Orchidea és átlátszó cserép | B8: Csak ha van ilyen termék – különben szűrő / említés | C8: =SUMIFS(C13:C34,A13:A34,A8,E13:E34,"<>Nem")
A9: Kaspó, virágláda, dekor cserép | B9: Nem growshop-téma – csak ha forgalmazod | C9: =SUMIFS(C13:C34,A13:A34,A9,E13:E34,"<>Nem")
A12: Terület | B12: Kulcsszó | C12: Havi keresés | D12: Kötődés a webshophoz | E12: Érdemes rá oldal? | F12: Javasolt felhasználás
A13: Önöntöző cserép | B13: önöntöző cserép | C13: 90 | D13: Laza | E13: Igen | F13: Nincs önöntöző cserép a kínálatban (csak egy víztartályos alátét) – kategória csak kínálatbővítés esetén
A14: Önöntöző cserép | B14: önöntöző virágcserép | C14: 20 | D14: Laza | E14: Igen | F14: Nincs önöntöző cserép a kínálatban (csak egy víztartályos alátét) – kategória csak kínálatbővítés esetén
A15: Önöntöző cserép | B15: cserép öntöző | C15: 20 | D15: Laza | E15: Igen | F15: Nincs önöntöző cserép a kínálatban (csak egy víztartályos alátét) – kategória csak kínálatbővítés esetén
A16: Önöntöző cserép | B16: önlocsoló virágcserép | C16: 10 | D16: Laza | E16: Igen | F16: Nincs önöntöző cserép a kínálatban (csak egy víztartályos alátét) – kategória csak kínálatbővítés esetén
A17: Műanyag vödör | B17: műanyag vödör | C17: 590 | D17: Laza | E17: Igen | F17: Csak ha van vödör (pl. DWC / hidro vödör) – akkor a Hidro ágba vagy szűrőként
A18: Műanyag vödör | B18: műanyagvödör | C18: 590 | D18: Laza | E18: Igen | F18: Csak ha van vödör (pl. DWC / hidro vödör) – akkor a Hidro ágba vagy szűrőként
A19: Műanyag vödör | B19: olcsó műanyag vödör | C19: 70 | D19: Laza | E19: Igen | F19: Csak ha van vödör (pl. DWC / hidro vödör) – akkor a Hidro ágba vagy szűrőként
A20: Műanyag vödör | B20: műanyag vödör fedővel | C20: 20 | D20: Laza | E20: Igen | F20: Csak ha van vödör (pl. DWC / hidro vödör) – akkor a Hidro ágba vagy szűrőként
A21: Hidrokultúrás cserép, hálós kosár | B21: hidrokultúrás cserép | C21: 30 | D21: Laza | E21: Igen | F21: A Hidro főkategóriába (ha van); innen kereszt-link
A22: Hidrokultúrás cserép, hálós kosár | B22: hálós kosár | C22: 20 | D22: Laza | E22: Igen | F22: A Hidro főkategóriába (ha van); innen kereszt-link
A23: Hidrokultúrás cserép, hálós kosár | B23: hidroponikus cserép | C23: 20 | D23: Laza | E23: Igen | F23: A Hidro főkategóriába (ha van); innen kereszt-link
A24: Hidrokultúrás cserép, hálós kosár | B24: hidro cserép | C24: 10 | D24: Laza | E24: Igen | F24: A Hidro főkategóriába (ha van); innen kereszt-link
... A34: Kaspó, virágláda, dekor cserép | B34: kerámia cserép | C34: 590 | D34: Laza | E34: Nem | F34: Nem growshop-téma – csak ha forgalmazod

Sheet Sandbox menünevek
A1: A sandbox „Cserép, tálca” menünevei – keresési volumen és javasolt név
A2: Sandbox-tervezet: Virágcserép; Speciális cserép, szövetcserép; Tálca, alátét.
A4: Régi kategória | B4: Javaslat (hova kerüljön) | C4: Releváns keresés (Szoros+Laza)
A5: Cserép, tálca (főkategória) | B5: A „cserép” (2900) tetőcserép, a „cserép tálca” / „cserép és tálca” kifejezésre nincs mérhető keresés. Menünévnek jó, a H1 / SEO title legyen: „Virágcserép, cserépalátét, tálca”. | C5: =SUMIFS(C12:C25,A12:A25,A5,E12:E25,"Igen")
A6: Virágcserép | B6: Marad; H1: „Műanyag virágcserép”, szűrők: liter, átmérő, forma | C6: =SUMIFS(C12:C25,A12:A25,A6,E12:E25,"Igen")
A7: Speciális cserép, szövetcserép | B7: A „speciális cserép” névre nincs keresés, a „szövetcserép”-re 10. Javaslat: két önálló alkategória – „Air-Pot cserép” és „Szövetcserép, ültetőzsák”. | C7: =SUMIFS(C12:C25,A12:A25,A7,E12:E25,"Igen")
A8: Tálca, alátét | B8: Az „alátét” (720) csavaralátét, a „tálcák” (1000) konyhai. Javaslat: kettébontás – „Cserépalátét” és „Műanyag tálca, árapály asztal”. | C8: =SUMIFS(C12:C25,A12:A25,A8,E12:E25,"Igen")
A11: Régi kategória | B11: Kulcsszó | C11: Havi keresés | D11: Kötődés a webshophoz | E11: Érdemes rá oldal? | F11: Javasolt felhasználás
A12: Cserép, tálca (főkategória) | B12: cserép | C12: 2900 | D12: Laza | E12: Nem | F12: Nem célozni külön oldallal (max. említés)
A13: Cserép, tálca (főkategória) | B13: virágcserép | C13: 2400 | D13: Szoros | E13: Igen | F13: Az új kategória leírásában / átirányítás (301) a régi URL-ről
A14: Cserép, tálca (főkategória) | B14: cserépalátét | C14: 260 | D14: Szoros | E14: Igen | F14: Az új kategória leírásában / átirányítás (301) a régi URL-ről
A15: Virágcserép | B15: virágcserép | C15: 2400 | D15: Szoros | E15: Igen | F15: Az új kategória leírásában / átirányítás (301) a régi URL-ről
A16: Virágcserép | B16: műanyag virágcserép | C16: 590 | D16: Szoros | E16: Igen | F16: Az új kategória leírásában / átirányítás (301) a régi URL-ről
A17: Speciális cserép, szövetcserép | B17: airpot | C17: 140 | D17: Szoros | E17: Igen | F17: Az új kategória leírásában / átirányítás (301) a régi URL-ről
A18: Speciális cserép, szövetcserép | B18: ültetőzsák | C18: 90 | D18: Szoros | E18: Igen | F18: Az új kategória leírásában / átirányítás (301) a régi URL-ről
A19: Speciális cserép, szövetcserép | B19: szövet cserép | C19: 20 | D19: Szoros | E19: Igen | F19: Az új kategória leírásában / átirányítás (301) a régi URL-ről
A20: Speciális cserép, szövetcserép | B20: szövetcserép | C20: 10 | D20: Szoros | E20: Igen | F20: Az új kategória leírásában / átirányítás (301) a régi URL-ről
A21: Tálca, alátét | B21: tálcák | C21: 1000 | D21: Laza | E21: Nem | F21: Nem célozni külön oldallal (max. említés)
A22: Tálca, alátét | B22: alátét | C22: 720 | D22: Laza | E22: Nem | F22: Nem célozni külön oldallal (max. említés)
A23: Tálca, alátét | B23: cserépalátét | C23: 260 | D23: Szoros | E23: Igen | F23: Az új kategória leírásában / átirányítás (301) a régi URL-ről
... A25: Tálca, alátét | B25: nagyméretű műanyag tálca | C25: 140 | D25: Laza | E25: Igen | F25: Az új kategória leírásában / átirányítás (301) a régi URL-ről

Sheet Összes kulcsszó
A1: Kategória | B1: # | C1: Kulcsszó | D1: Megjegyzés (szint) | E1: Havi keresés | F1: Kötődés a webshophoz | G1: Érdemes rá kategória/oldal? | H1: Felhasználási terület | I1: Javasolt felhasználás
A2: Virágcserép | B2: 1 | C2: virágcserép | E2: 2400 | F2: Szoros | G2: Igen | H2: Termesztő cserép – műanyag, kerek, literes méretek | I2: Kategórianév + H1 + SEO title (fő kulcsszó)
A3: Műanyag tálca, árapály asztal | B3: 2 | C3: tálcák | E3: 1000 | F3: Laza | G3: Nem | H3: Gyűjtőtálca termesztősátorba, árapály (ebb & flow) rendszer | I3: Nem célozni külön oldallal (max. említés)
A4: Cserépalátét | B4: 2 | C4: alátét | E4: 720 | F4: Laza | G4: Nem | H4: Cserép alá – vízfelfogás, gurulós alátét | I4: Nem célozni külön oldallal (max. említés)
A5: Virágcserép | B5: 2 | C5: műanyag virágcserép | E5: 590 | F5: Szoros | G5: Igen | H5: Termesztő cserép – műanyag, kerek, literes méretek | I5: SEO title / H1 / bevezető (másodlagos)
A6: Virágcserép | B6: 3 | C6: műanyag virág cserép | E6: 590 | F6: Szoros | G6: Igen | H6: Termesztő cserép – műanyag, kerek, literes méretek | I6: Kategórialeírás (természetes említés)
A7: Műanyag tálca, árapály asztal | B7: 3 | C7: műanyag tálca | E7: 590 | F7: Laza | G7: Igen | H7: Gyűjtőtálca termesztősátorba, árapály (ebb & flow) rendszer | I7: SEO title / H1 / bevezető (másodlagos)
A8: Virágcserép | B8: 4 | C8: műanyag cserép | E8: 480 | F8: Szoros | G8: Igen | H8: Termesztő cserép – műanyag, kerek, literes méretek | I8: SEO title / H1 / bevezető (másodlagos)
A9: Virágcserép | B9: 5 | C9: műanyagcserép | E9: 480 | F9: Szoros | G9: Igen | H9: Termesztő cserép – műanyag, kerek, literes méretek | I9: Kategórialeírás (természetes említés)
A10: Nagy virágcserép | B10: 1 | C10: nagy virágcserép | E10: 480 | F10: Szoros | G10: Igen | H10: Nagy térfogatú cserép – 20–100 literes termesztés, kültér | I10: Kategórianév + H1 + SEO title (fő kulcsszó)
A11: Műanyag tálca, árapály asztal | B11: 4 | C11: kármentő tálca | E11: 480 | F11: Laza | G11: Nem | H11: Gyűjtőtálca termesztősátorba, árapály (ebb & flow) rendszer | I11: Nem célozni külön oldallal (max. említés)
A12: Nagy virágcserép | B12: 2 | C12: műanyag virágcserép 100 cm | E12: 390 | F12: Laza | G12: Nem | H12: Nagy térfogatú cserép – 20–100 literes termesztés, kültér | I12: Nem célozni külön oldallal (max. említés)
A13: Virágcserép | B13: 6 | C13: obi virágcserép | E13: 320 | F13: Nincs (áruházi / nem vásárlási szándék) | G13: Nem – kizárandó | H13: Termesztő cserép – műanyag, kerek, literes méretek | I13: Nem használni (áruházi/nem vásárlási szándék)
... A119: Műanyag tálca, árapály asztal | B119: 21 | C119: kerti tálca | E119: 10 | F119: Szoros | G119: Igen | H119: Gyűjtőtálca termesztősátorba, árapály (ebb & flow) rendszer | I119: Kategórialeírás (természetes említés)

Sheet 1 Virágcserép
A1: Virágcserép – fő kulcsszó: „virágcserép”
A2: Felhasználási terület: Termesztő cserép – műanyag, kerek, literes méretek
A3: Megjegyzés: A literes keresések kicsik (20 literes 50, 10 literes 30, 50 literes 30, 30 literes 20, 15 literes 20) – a térfogat legyen szűrő, ne kategória. A „cserép” (2900) önmagában tetőcserép, a „műanyag vödör” (590) a Bővítés lapon van.
A4: Felvett releváns kulcsszavak: 30 (a Kulcsszótervező > 0 keresésű ötleteiből válogatva; a teljes nyers lista a CSV-ben)
A6: # | B6: Kulcsszó | C6: Havi keresés | D6: Kötődés a webshophoz | E6: Érdemes rá kategória/oldal? | F6: Felhasználási terület | G6: Javasolt felhasználás
A7: 1 | B7: virágcserép | C7: 2400 | D7: Szoros | E7: Igen | F7: Termesztő cserép – műanyag, kerek, literes méretek | G7: Kategórianév + H1 + SEO title (fő kulcsszó)
A8: 2 | B8: műanyag virágcserép | C8: 590 | D8: Szoros | E8: Igen | F8: Termesztő cserép – műanyag, kerek, literes méretek | G8: SEO title / H1 / bevezető (másodlagos)
A9: 3 | B9: műanyag virág cserép | C9: 590 | D9: Szoros | E9: Igen | F9: Termesztő cserép – műanyag, kerek, literes méretek | G9: Kategórialeírás (természetes említés)
A10: 4 | B10: műanyag cserép | C10: 480 | D10: Szoros | E10: Igen | F10: Termesztő cserép – műanyag, kerek, literes méretek | G10: SEO title / H1 / bevezető (másodlagos)
A11: 5 | B11: műanyagcserép | C11: 480 | D11: Szoros | E11: Igen | F11: Termesztő cserép – műanyag, kerek, literes méretek | G11: Kategórialeírás (természetes említés)
A12: 6 | B12: obi virágcserép | C12: 320 | D12: Nincs (áruházi / nem vásárlási szándék) | E12: Nem – kizárandó | F12: Termesztő cserép – műanyag, kerek, literes méretek | G12: Nem használni (áruházi/nem vásárlási szándék)
A13: 7 | B13: virágcserép műanyag | C13: 260 | D13: Szoros | E13: Igen | F13: Termesztő cserép – műanyag, kerek, literes méretek | G13: Kategórialeírás (természetes említés)
A14: 8 | B14: könnyű cserepek | C14: 140 | D14: Szoros | E14: Igen | F14: Termesztő cserép – műanyag, kerek, literes méretek | G14: Kategórialeírás (természetes említés)
A15: 9 | B15: cserepek | C15: 140 | D15: Szoros | E15: Igen | F15: Termesztő cserép – műanyag, kerek, literes méretek | G15: Kategórialeírás (természetes említés)
A16: 10 | B16: praktiker virágcserép | C16: 140 | D16: Nincs (áruházi / nem vásárlási szándék) | E16: Nem – kizárandó | F16: Termesztő cserép – műanyag, kerek, literes méretek | G16: Nem használni (áruházi/nem vásárlási szándék)
A17: 11 | B17: olcsó műanyag virágcserép | C17: 110 | D17: Szoros | E17: Igen | F17: Termesztő cserép – műanyag, kerek, literes méretek | G17: Kategórialeírás (természetes említés)
A18: 12 | B18: virágcserepek | C18: 110 | D18: Szoros | E18: Igen | F18: Termesztő cserép – műanyag, kerek, literes méretek | G18: Kategórialeírás (természetes említés)
... A36: 30 | B36: műanyag palántázó cserép | C36: 10 | D36: Szoros | E36: Igen | F36: Termesztő cserép – műanyag, kerek, literes méretek | G36: Kategórialeírás (természetes említés)
B37: Összesen (érdemes rá oldal = Igen): | C37: =SUMIFS(C7:C36,E7:E36,"Igen")
A39: Termékek a jelenlegi kínálatból: 57 db (elsődleges + másodlagos hozzárendelés; egy termék több kategóriában is szerepelhet)
A40: # | B40: Termékkód | C40: Terméknév | D40: Hozzárendelés | E40: Illeszkedés | F40: Megjegyzés
A41: 1 | B41: GRO0067 | C41: Szögletes műanyag cserép 6 liter, 17,5 x 17,5 x 25 cm, gyökércsavarodás gátló | D41: Elsődleges | E41: Erős | F41: Szögletes, gyökércsavarodás-gátló
A42: 2 | B42: GRO0068 | C42: Görög mintás négyzetes műanyag virágcserép 18 liter, 30,5 x 30,5 cm | D42: Elsődleges | E42: Erős | F42: Görög mintás négyzetes
A43: 3 | B43: GRO0069 | C43: Görög mintás négyzetes műanyag virágcserép 25 liter, 33,5 x 33,5 cm | D43: Elsődleges | E43: Erős | F43: Görög mintás négyzetes, 25–30 l
A44: 4 | B44: GRO0070 | C44: Görög mintás négyzetes műanyag virágcserép 30 liter, 36,5 x 36,5 cm | D44: Elsődleges | E44: Erős | F44: Görög mintás négyzetes, 25–30 l
A45: 5 | B45: GRO0748 | C45: Görög mintás négyzetes műanyag virágcserép 9 liter, 23 x 23 cm | D45: Elsődleges | E45: Erős | F45: Görög mintás négyzetes
A46: 6 | B46: GRO1141 | C46: Szögletes műanyag cserép 2,5 liter, 13 x 13 x 18 cm, gyökércsavarodás gátló | D46: Elsődleges | E46: Erős | F46: Szögletes, gyökércsavarodás-gátló
A47: 7 | B47: GRO1143 | C47: Görög mintás négyzetes műanyag virágcserép 14 liter, 28,5 x 28,5 cm | D47: Elsődleges | E47: Erős | F47: Görög mintás négyzetes
A48: 8 | B48: GRO1160 | C48: Szögletes műanyag cserép 1,4 liter, 10 x 10 x 17 cm, gyökércsavarodás gátló | D48: Elsődleges | E48: Erős | F48: Szögletes, gyökércsavarodás-gátló
A49: 9 | B49: GRO1161 | C49: Szögletes műanyag cserép 1,8 liter, 10,5 x 8,5 x 22 cm, gyökércsavarodás gátló | D49: Elsődleges | E49: Erős | F49: Szögletes, gyökércsavarodás-gátló
A50: 10 | B50: GRO1189 | C50: Görög mintás négyzetes műanyag virágcserép 11 liter, 25 x 25 cm | D50: Elsődleges | E50: Erős | F50: Görög mintás négyzetes
A51: 11 | B51: GRO1259 | C51: Szögletes műanyag cserép 1,5 liter, 12 x 12 x 13 cm, gyökércsavarodás gátló | D51: Elsődleges | E51: Erős | F51: Szögletes, gyökércsavarodás-gátló
A52: 12 | B52: GRO1261 | C52: Szögletes műanyag cserép 15 x 15 x 20 cm, gyökércsavarodás gátló | D52: Elsődleges | E52: Erős | F52: Szögletes, gyökércsavarodás-gátló
... A97: 57 | B97: GRO4653 | C97: Kerek műanyag konténer fogantyúval, 155 L (70x51 cm) | D97: Másodlagos | E97: Erős | F97: Konténer, 43–155 l

Sheet 2 Nagy virágcserép
A1: Nagy virágcserép – fő kulcsszó: „nagy virágcserép”
A2: Felhasználási terület: Nagy térfogatú cserép – 20–100 literes termesztés, kültér
A3: Megjegyzés: Erős klaszter (nagy virágcserép 480, nagyméretű műanyag virágcserép 320, virágcserép nagy 260). A „műanyag virágcserép 100 cm” (390) / „60 cm” (320) főleg dekor balkon- és teraszcserép.
A4: Felvett releváns kulcsszavak: 14 (a Kulcsszótervező > 0 keresésű ötleteiből válogatva; a teljes nyers lista a CSV-ben)
A6: # | B6: Kulcsszó | C6: Havi keresés | D6: Kötődés a webshophoz | E6: Érdemes rá kategória/oldal? | F6: Felhasználási terület | G6: Javasolt felhasználás
A7: 1 | B7: nagy virágcserép | C7: 480 | D7: Szoros | E7: Igen | F7: Nagy térfogatú cserép – 20–100 literes termesztés, kültér | G7: Kategórianév + H1 + SEO title (fő kulcsszó)
A8: 2 | B8: műanyag virágcserép 100 cm | C8: 390 | D8: Laza | E8: Nem | F8: Nagy térfogatú cserép – 20–100 literes termesztés, kültér | G8: Nem célozni külön oldallal (max. említés)
A9: 3 | B9: nagyméretű műanyag virágcserép | C9: 320 | D9: Szoros | E9: Igen | F9: Nagy térfogatú cserép – 20–100 literes termesztés, kültér | G9: SEO title / H1 / bevezető (másodlagos)
A10: 4 | B10: műanyag virágcserép 60 cm | C10: 320 | D10: Laza | E10: Nem | F10: Nagy térfogatú cserép – 20–100 literes termesztés, kültér | G10: Nem célozni külön oldallal (max. említés)
A11: 5 | B11: virágcserép nagy | C11: 260 | D11: Szoros | E11: Igen | F11: Nagy térfogatú cserép – 20–100 literes termesztés, kültér | G11: SEO title / H1 / bevezető (másodlagos)
A12: 6 | B12: nagy cserép | C12: 140 | D12: Szoros | E12: Igen | F12: Nagy térfogatú cserép – 20–100 literes termesztés, kültér | G12: SEO title / H1 / bevezető (másodlagos)
A13: 7 | B13: nagy méretű virágcserép | C13: 90 | D13: Szoros | E13: Igen | F13: Nagy térfogatú cserép – 20–100 literes termesztés, kültér | G13: Kategórialeírás (természetes említés)
A14: 8 | B14: nagyméretű cserép | C14: 70 | D14: Szoros | E14: Igen | F14: Nagy térfogatú cserép – 20–100 literes termesztés, kültér | G14: Kategórialeírás (természetes említés)
A15: 9 | B15: nagy virágcserép olcsón | C15: 70 | D15: Szoros | E15: Igen | F15: Nagy térfogatú cserép – 20–100 literes termesztés, kültér | G15: Kategórialeírás (természetes említés)
A16: 10 | B16: nagy műanyag cserép | C16: 50 | D16: Szoros | E16: Igen | F16: Nagy térfogatú cserép – 20–100 literes termesztés, kültér | G16: Kategórialeírás (természetes említés)
A17: 11 | B17: nagy műanyag virágcserép | C17: 40 | D17: Szoros | E17: Igen | F17: Nagy térfogatú cserép – 20–100 literes termesztés, kültér | G17: Kategórialeírás (természetes említés)
A18: 12 | B18: nagyméretű műanyag cserép | C18: 40 | D18: Szoros | E18: Igen | F18: Nagy térfogatú cserép – 20–100 literes termesztés, kültér | G18: Kategórialeírás (természetes említés)
... A20: 14 | B20: 50 literes virágcserép | C20: 20 | D20: Szoros | E20: Igen | F20: Nagy térfogatú cserép – 20–100 literes termesztés, kültér | G20: Kategórialeírás (természetes említés)
B21: Összesen (érdemes rá oldal = Igen): | C21: =SUMIFS(C7:C20,E7:E20,"Igen")
A23: Termékek a jelenlegi kínálatból: 25 db (elsődleges + másodlagos hozzárendelés; egy termék több kategóriában is szerepelhet)
A24: # | B24: Termékkód | C24: Terméknév | D24: Hozzárendelés | E24: Illeszkedés | F24: Megjegyzés
A25: 1 | B25: GRO2501 | C25: Lyukacsos konténer műanyag cserép 43 liter | D25: Elsődleges | E25: Erős | F25: Konténer, 43–155 l
A26: 2 | B26: GRO2502 | C26: Lyukacsos konténer műanyag cserép 50 liter | D26: Elsődleges | E26: Erős | F26: Konténer, 43–155 l
A27: 3 | B27: GRO2503 | C27: Lyukacsos konténer műanyag cserép 60 liter | D27: Elsődleges | E27: Erős | F27: Konténer, 43–155 l
A28: 4 | B28: GRO2504 | C28: Lyukacsos konténer műanyag cserép 70 liter | D28: Elsődleges | E28: Erős | F28: Konténer, 43–155 l
A29: 5 | B29: GRO2505 | C29: Lyukacsos konténer műanyag cserép 80 liter, 60 x 43 cm, fogantyúval | D29: Elsődleges | E29: Erős | F29: Konténer, 43–155 l
A30: 6 | B30: GRO2506 | C30: Lyukacsos konténer műanyag cserép 100 liter, 60 x 51 cm, fogantyúval | D30: Elsődleges | E30: Erős | F30: Konténer, 43–155 l
A31: 7 | B31: GRO4644 | C31: Kerek műanyag konténer fogantyúval, 43 L (45x34 cm) | D31: Elsődleges | E31: Erős | F31: Konténer, 43–155 l
A32: 8 | B32: GRO4645 | C32: Kerek műanyag konténer fogantyúval, 50 L (45x41 cm) | D32: Elsődleges | E32: Erős | F32: Konténer, 43–155 l
A33: 9 | B33: GRO4646 | C33: Kerek műanyag konténer fogantyúval, 60 L (50x38 cm) | D33: Elsődleges | E33: Erős | F33: Konténer, 43–155 l
A34: 10 | B34: GRO4647 | C34: Kerek műanyag konténer fogantyúval, 70 L (50x44 cm) | D34: Elsődleges | E34: Erős | F34: Konténer, 43–155 l
A35: 11 | B35: GRO4648 | C35: Kerek műanyag konténer fogantyúval, 80 L (55x43 cm) | D35: Elsődleges | E35: Erős | F35: Konténer, 43–155 l
A36: 12 | B36: GRO4649 | C36: Kerek műanyag konténer fogantyúval 100 L (55x51 cm) | D36: Elsődleges | E36: Erős | F36: Konténer, 43–155 l
... A49: 25 | B49: GRO2571 | C49: Air-Pot klón 50 literes perforált, légáteresztő műanyag edény erős gyökérzethez | D49: Másodlagos | E49: Erős | F49: Air-Pot klón 50 l

Sheet 3 Szögletes cserép
A1: Szögletes cserép – fő kulcsszó: „szögletes virágcserép”
A2: Felhasználási terület: Helytakarékos termesztés sátorban / polcon
A3: Megjegyzés: A „négyzetes cserép” kifejezésre nincs mérhető keresés – a „szögletes” a vásárlói szó.
A4: Felvett releváns kulcsszavak: 9 (a Kulcsszótervező > 0 keresésű ötleteiből válogatva; a teljes nyers lista a CSV-ben)
A6: # | B6: Kulcsszó | C6: Havi keresés | D6: Kötődés a webshophoz | E6: Érdemes rá kategória/oldal? | F6: Felhasználási terület | G6: Javasolt felhasználás
A7: 1 | B7: szögletes virágcserép | C7: 90 | D7: Szoros | E7: Igen | F7: Helytakarékos termesztés sátorban / polcon | G7: Kategórianév + H1 + SEO title (fő kulcsszó)
A8: 2 | B8: magas cserép | C8: 70 | D8: Szoros | E8: Igen | F8: Helytakarékos termesztés sátorban / polcon | G8: SEO title / H1 / bevezető (másodlagos)
A9: 3 | B9: szögletes cserép | C9: 40 | D9: Szoros | E9: Igen | F9: Helytakarékos termesztés sátorban / polcon | G9: SEO title / H1 / bevezető (másodlagos)
A10: 4 | B10: szögletes műanyag cserép | C10: 30 | D10: Szoros | E10: Igen | F10: Helytakarékos termesztés sátorban / polcon | G10: SEO title / H1 / bevezető (másodlagos)
A11: 5 | B11: magas műanyag virágcserép | C11: 20 | D11: Szoros | E11: Igen | F11: Helytakarékos termesztés sátorban / polcon | G11: Kategórialeírás (természetes említés)
A12: 6 | B12: négyszögletes virágcserép | C12: 20 | D12: Szoros | E12: Igen | F12: Helytakarékos termesztés sátorban / polcon | G12: Kategórialeírás (természetes említés)
A13: 7 | B13: négyzet alakú virágcserép | C13: 20 | D13: Szoros | E13: Igen | F13: Helytakarékos termesztés sátorban / polcon | G13: Kategórialeírás (természetes említés)
A14: 8 | B14: négyszögletes műanyag cserép | C14: 10 | D14: Szoros | E14: Igen | F14: Helytakarékos termesztés sátorban / polcon | G14: Kategórialeírás (természetes említés)
A15: 9 | B15: mély cserép | C15: 10 | D15: Szoros | E15: Igen | F15: Helytakarékos termesztés sátorban / polcon | G15: Kategórialeírás (természetes említés)
B16: Összesen (érdemes rá oldal = Igen): | C16: =SUMIFS(C7:C15,E7:E15,"Igen")
A18: Termékek a jelenlegi kínálatból: 24 db (elsődleges + másodlagos hozzárendelés; egy termék több kategóriában is szerepelhet)
A19: # | B19: Termékkód | C19: Terméknév | D19: Hozzárendelés | E19: Illeszkedés | F19: Megjegyzés
A20: 1 | B20: GRO0067 | C20: Szögletes műanyag cserép 6 liter, 17,5 x 17,5 x 25 cm, gyökércsavarodás gátló | D20: Másodlagos | E20: Erős | F20: Szögletes, gyökércsavarodás-gátló
A21: 2 | B21: GRO0068 | C21: Görög mintás négyzetes műanyag virágcserép 18 liter, 30,5 x 30,5 cm | D21: Másodlagos | E21: Erős | F21: Görög mintás négyzetes
A22: 3 | B22: GRO0069 | C22: Görög mintás négyzetes műanyag virágcserép 25 liter, 33,5 x 33,5 cm | D22: Másodlagos | E22: Erős | F22: Görög mintás négyzetes, 25–30 l
A23: 4 | B23: GRO0070 | C23: Görög mintás négyzetes műanyag virágcserép 30 liter, 36,5 x 36,5 cm | D23: Másodlagos | E23: Erős | F23: Görög mintás négyzetes, 25–30 l
A24: 5 | B24: GRO0748 | C24: Görög mintás négyzetes műanyag virágcserép 9 liter, 23 x 23 cm | D24: Másodlagos | E24: Erős | F24: Görög mintás négyzetes
A25: 6 | B25: GRO1141 | C25: Szögletes műanyag cserép 2,5 liter, 13 x 13 x 18 cm, gyökércsavarodás gátló | D25: Másodlagos | E25: Erős | F25: Szögletes, gyökércsavarodás-gátló
A26: 7 | B26: GRO1143 | C26: Görög mintás négyzetes műanyag virágcserép 14 liter, 28,5 x 28,5 cm | D26: Másodlagos | E26: Erős | F26: Görög mintás négyzetes
A27: 8 | B27: GRO1160 | C27: Szögletes műanyag cserép 1,4 liter, 10 x 10 x 17 cm, gyökércsavarodás gátló | D27: Másodlagos | E27: Erős | F27: Szögletes, gyökércsavarodás-gátló
A28: 9 | B28: GRO1161 | C28: Szögletes műanyag cserép 1,8 liter, 10,5 x 8,5 x 22 cm, gyökércsavarodás gátló | D28: Másodlagos | E28: Erős | F28: Szögletes, gyökércsavarodás-gátló
A29: 10 | B29: GRO1189 | C29: Görög mintás négyzetes műanyag virágcserép 11 liter, 25 x 25 cm | D29: Másodlagos | E29: Erős | F29: Görög mintás négyzetes
A30: 11 | B30: GRO1259 | C30: Szögletes műanyag cserép 1,5 liter, 12 x 12 x 13 cm, gyökércsavarodás gátló | D30: Másodlagos | E30: Erős | F30: Szögletes, gyökércsavarodás-gátló
A31: 12 | B31: GRO1261 | C31: Szögletes műanyag cserép 15 x 15 x 20 cm, gyökércsavarodás gátló | D31: Másodlagos | E31: Erős | F31: Szögletes, gyökércsavarodás-gátló
... A43: 24 | B43: GRO4626 | C43: Négyzetes cserép 4x4 cm | D43: Másodlagos | E43: Laza | F43: Palántázó kiscserép (4–9 cm)

Sheet 4 Air-Pot
A1: Air-Pot cserép – fő kulcsszó: „airpot”
A2: Felhasználási terület: Gyökérlégzés, gyökérmetszés – termesztés konténerben
A3: Megjegyzés: A „légmetsző / légmetszéses / gyökérlégző cserép” kifejezésekre nincs mérhető keresés – a vásárlók a márkanevet keresik.
A4: Felvett releváns kulcsszavak: 5 (a Kulcsszótervező > 0 keresésű ötleteiből válogatva; a teljes nyers lista a CSV-ben)
A6: # | B6: Kulcsszó | C6: Havi keresés | D6: Kötődés a webshophoz | E6: Érdemes rá kategória/oldal? | F6: Felhasználási terület | G6: Javasolt felhasználás
A7: 1 | B7: airpot | C7: 140 | D7: Szoros | E7: Igen | F7: Gyökérlégzés, gyökérmetszés – termesztés konténerben | G7: Kategórianév + H1 + SEO title (fő kulcsszó)
A8: 2 | B8: air pot | C8: 90 | D8: Szoros | E8: Igen | F8: Gyökérlégzés, gyökérmetszés – termesztés konténerben | G8: SEO title / H1 / bevezető (másodlagos)
A9: 3 | B9: air pot 50l | C9: 10 | D9: Szoros | E9: Igen | F9: Gyökérlégzés, gyökérmetszés – termesztés konténerben | G9: Gyártóoldal / szűrő / termékoldal
A10: 4 | B10: air pot hydro | C10: 10 | D10: Szoros | E10: Igen | F10: Gyökérlégzés, gyökérmetszés – termesztés konténerben | G10: Gyártóoldal / szűrő / termékoldal
A11: 5 | B11: air pot 9l | C11: 10 | D11: Szoros | E11: Igen | F11: Gyökérlégzés, gyökérmetszés – termesztés konténerben | G11: Gyártóoldal / szűrő / termékoldal
B12: Összesen (érdemes rá oldal = Igen): | C12: =SUMIFS(C7:C11,E7:E11,"Igen")
A14: Termékek a jelenlegi kínálatból: 13 db (elsődleges + másodlagos hozzárendelés; egy termék több kategóriában is szerepelhet)
A15: # | B15: Termékkód | C15: Terméknév | D15: Hozzárendelés | E15: Illeszkedés | F15: Megjegyzés
A16: 1 | B16: GRO1890 | C16: Air-Pot klón 1 literes perforált, légáteresztő műanyag edény erős gyökérzethez | D16: Elsődleges | E16: Erős | F16: Air-Pot (klón) perforált cserép
A17: 2 | B17: GRO1891 | C17: Air-Pot klón 3 literes perforált, légáteresztő műanyag edény erős gyökérzethez | D17: Elsődleges | E17: Erős | F17: Air-Pot (klón) perforált cserép
A18: 3 | B18: GRO1892 | C18: Air-Pot klón 6 literes perforált, légáteresztő műanyag edény erős gyökérzethez | D18: Elsődleges | E18: Erős | F18: Air-Pot (klón) perforált cserép
A19: 4 | B19: GRO1893 | C19: Air-Pot klón 10 literes perforált, légáteresztő műanyag edény erős gyökérzethez | D19: Elsődleges | E19: Erős | F19: Air-Pot (klón) perforált cserép
A20: 5 | B20: GRO1894 | C20: Air-Pot klón 15 literes perforált, légáteresztő műanyag edény erős gyökérzethez | D20: Elsődleges | E20: Erős | F20: Air-Pot (klón) perforált cserép
A21: 6 | B21: GRO1895 | C21: Air-Pot klón 25 literes perforált, légáteresztő műanyag edény erős gyökérzethez | D21: Elsődleges | E21: Erős | F21: Air-Pot (klón) perforált cserép
A22: 7 | B22: GRO2571 | C22: Air-Pot klón 50 literes perforált, légáteresztő műanyag edény erős gyökérzethez | D22: Elsődleges | E22: Erős | F22: Air-Pot klón 50 l
A23: 8 | B23: GRO3346 | C23: Air-pot cserép 3 liter | D23: Elsődleges | E23: Erős | F23: Air-Pot (klón) perforált cserép
A24: 9 | B24: GRO3525 | C24: Air-pot cserép 5 liter | D24: Elsődleges | E24: Erős | F24: Air-Pot (klón) perforált cserép
A25: 10 | B25: GRO3526 | C25: Air-pot cserép 9 liter | D25: Elsődleges | E25: Erős | F25: Air-Pot (klón) perforált cserép
A26: 11 | B26: GRO3348 | C26: Venti Pot hidro cserép 3,5 liter | D26: Másodlagos | E26: Laza | F26: Venti Pot – perforált hidro cserép
A27: 12 | B27: GRO3349 | C27: Venti Pot hidro cserép 12 liter | D27: Másodlagos | E27: Laza | F27: Venti Pot – perforált hidro cserép
A28: 13 | B28: GRO3350 | C28: Venti Pot hidro cserép 25 liter | D28: Másodlagos | E28: Laza | F28: Venti Pot – perforált hidro cserép

Sheet 5 Szövetcserép
A1: Szövetcserép, ültetőzsák – fő kulcsszó: „ültetőzsák”
A2: Felhasználási terület: Szövet / textil / filc cserép, ültető- és termesztőzsák
A3: Megjegyzés: A „szövetcserép” egybeírva csak 10; a „szövet cserép”, „textil cserép”, „textil virágcserép”, „smart pot”, „grow bag” egyenként 20. A legerősebb az „ültetőzsák” (90 + ékezet nélkül 50), de ennek egy része burgonyás zsák.
A4: Felvett releváns kulcsszavak: 16 (a Kulcsszótervező > 0 keresésű ötleteiből válogatva; a teljes nyers lista a CSV-ben)
A6: # | B6: Kulcsszó | C6: Havi keresés | D6: Kötődés a webshophoz | E6: Érdemes rá kategória/oldal? | F6: Felhasználási terület | G6: Javasolt felhasználás
A7: 1 | B7: ültetőzsák | C7: 90 | D7: Szoros | E7: Igen | F7: Szövet / textil / filc cserép, ültető- és termesztőzsák | G7: Kategórianév + H1 + SEO title (fő kulcsszó)
A8: 2 | B8: ultetozsak | C8: 50 | D8: Szoros | E8: Igen | F8: Szövet / textil / filc cserép, ültető- és termesztőzsák | G8: Kategórialeírás (természetes említés)
A9: 3 | B9: burgonya ültető zsák | C9: 40 | D9: Laza | E9: Igen | F9: Szövet / textil / filc cserép, ültető- és termesztőzsák | G9: Kategórialeírás (természetes említés)
A10: 4 | B10: krumpli ültető zsák | C10: 40 | D10: Laza | E10: Igen | F10: Szövet / textil / filc cserép, ültető- és termesztőzsák | G10: Kategórialeírás (természetes említés)
A11: 5 | B11: szövet cserép | C11: 20 | D11: Szoros | E11: Igen | F11: Szövet / textil / filc cserép, ültető- és termesztőzsák | G11: SEO title / H1 / bevezető (másodlagos)
A12: 6 | B12: textil cserép | C12: 20 | D12: Szoros | E12: Igen | F12: Szövet / textil / filc cserép, ültető- és termesztőzsák | G12: SEO title / H1 / bevezető (másodlagos)
A13: 7 | B13: textil virágcserép | C13: 20 | D13: Szoros | E13: Igen | F13: Szövet / textil / filc cserép, ültető- és termesztőzsák | G13: SEO title / H1 / bevezető (másodlagos)
A14: 8 | B14: smart pot | C14: 20 | D14: Szoros | E14: Igen | F14: Szövet / textil / filc cserép, ültető- és termesztőzsák | G14: Kategórialeírás (természetes említés)
A15: 9 | B15: grow bag | C15: 20 | D15: Szoros | E15: Igen | F15: Szövet / textil / filc cserép, ültető- és termesztőzsák | G15: Kategórialeírás (természetes említés)
A16: 10 | B16: krumpli termesztő zsák | C16: 20 | D16: Laza | E16: Igen | F16: Szövet / textil / filc cserép, ültető- és termesztőzsák | G16: Kategórialeírás (természetes említés)
A17: 11 | B17: szövetcserép | C17: 10 | D17: Szoros | E17: Igen | F17: Szövet / textil / filc cserép, ültető- és termesztőzsák | G17: Kategórialeírás (természetes említés)
A18: 12 | B18: growbag | C18: 10 | D18: Szoros | E18: Igen | F18: Szövet / textil / filc cserép, ültető- és termesztőzsák | G18: Kategórialeírás (természetes említés)
... A22: 16 | B22: smarpot | C22: 10 | D22: Szoros | E22: Igen | F22: Szövet / textil / filc cserép, ültető- és termesztőzsák | G22: Kategórialeírás (természetes említés)
B23: Összesen (érdemes rá oldal = Igen): | C23: =SUMIFS(C7:C22,E7:E22,"Igen")
A25: Termékek a jelenlegi kínálatból: 28 db (elsődleges + másodlagos hozzárendelés; egy termék több kategóriában is szerepelhet)
A26: # | B26: Termékkód | C26: Terméknév | D26: Hozzárendelés | E26: Illeszkedés | F26: Megjegyzés
A27: 1 | B27: GRO0822 | C27: Szövet edény 3 liter, Smart Pot klón légáteresztő textilcserép | D27: Elsődleges | E27: Erős | F27: Szövet- / textilcserép (Smart Pot típus)
A28: 2 | B28: GRO0823 | C28: Szövet edény 15 liter, Smart Pot klón légáteresztő textilcserép | D28: Elsődleges | E28: Erős | F28: Szövet- / textilcserép (Smart Pot típus)
A29: 3 | B29: GRO0824 | C29: Szövet edény 25 liter, Smart Pot klón légáteresztő textilcserép | D29: Elsődleges | E29: Erős | F29: Szövet- / textilcserép (Smart Pot típus)
A30: 4 | B30: GRO1110 | C30: Szövet edény 7 liter, Smart Pot klón légáteresztő textilcserép | D30: Elsődleges | E30: Erős | F30: Szövet- / textilcserép (Smart Pot típus)
A31: 5 | B31: GRO1111 | C31: Szövet edény 10 liter, Smart Pot klón légáteresztő textilcserép | D31: Elsődleges | E31: Erős | F31: Szövet- / textilcserép (Smart Pot típus)
A32: 6 | B32: GRO2492 | C32: Szövet edény 1 liter, Smart Pot klón légáteresztő textilcserép | D32: Elsődleges | E32: Erős | F32: Szövet- / textilcserép (Smart Pot típus)
A33: 7 | B33: GRO2572 | C33: Szövet edény 50 liter, Smart Pot klón légáteresztő textilcserép | D33: Elsődleges | E33: Erős | F33: Nagy szövetcserép, 39–550 l
A34: 8 | B34: GRO3225 | C34: Urban Garden szövetcserép 4 liter, légáteresztő textil termesztőedény (14 x 14 x 20 cm) | D34: Elsődleges | E34: Erős | F34: Szövet- / textilcserép (Smart Pot típus)
A35: 9 | B35: GRO3226 | C35: Urban Garden szövetcserép 8 liter, légáteresztő textil termesztőedény (18 x 18 x 25,5 cm) | D35: Elsődleges | E35: Erős | F35: Szövet- / textilcserép (Smart Pot típus)
A36: 10 | B36: GRO3227 | C36: Urban Garden szövetcserép 11 liter | D36: Elsődleges | E36: Erős | F36: Szövet- / textilcserép (Smart Pot típus)
A37: 11 | B37: GRO3228 | C37: Urban Garden szövetcserép 15 liter, légáteresztő textil termesztőedény (23 x 23 x 29,5 cm) | D37: Elsődleges | E37: Erős | F37: Szövet- / textilcserép (Smart Pot típus)
A38: 12 | B38: GRO3229 | C38: Urban Garden szövetcserép 25 liter | D38: Elsődleges | E38: Erős | F38: Szövet- / textilcserép (Smart Pot típus)
... A54: 28 | B54: GRO4698 | C54: Kókuszrost ültetőzsák UGro Coco Pot9 Basic 9 L, préselt kókusztömb | D54: Másodlagos | E54: Laza | F54: Kókuszrost ültetőzsák (közeg + edény)

Sheet 6 Cserépalátét
A1: Cserépalátét – fő kulcsszó: „cserépalátét”
A2: Felhasználási terület: Cserép alá – vízfelfogás, gurulós alátét
A3: Megjegyzés: A „cserépalátét” és a „cserép alátét” egyenként 260; a „virágcserép alátéttel” (140) a cseréppel együtt vásárlót jelenti – a Virágcserép kategóriában is említendő.
A4: Felvett releváns kulcsszavak: 23 (a Kulcsszótervező > 0 keresésű ötleteiből válogatva; a teljes nyers lista a CSV-ben)
A6: # | B6: Kulcsszó | C6: Havi keresés | D6: Kötődés a webshophoz | E6: Érdemes rá kategória/oldal? | F6: Felhasználási terület | G6: Javasolt felhasználás
A7: 1 | B7: cserépalátét | C7: 260 | D7: Szoros | E7: Igen | F7: Cserép alá – vízfelfogás, gurulós alátét | G7: Kategórianév + H1 + SEO title (fő kulcsszó)
A8: 2 | B8: alátét | C8: 720 | D8: Laza | E8: Nem | F8: Cserép alá – vízfelfogás, gurulós alátét | G8: Nem célozni külön oldallal (max. említés)
A9: 3 | B9: obi cserépalátét | C9: 320 | D9: Nincs (áruházi / nem vásárlási szándék) | E9: Nem – kizárandó | F9: Cserép alá – vízfelfogás, gurulós alátét | G9: Nem használni (áruházi/nem vásárlási szándék)
A10: 4 | B10: cserép alátét | C10: 260 | D10: Szoros | E10: Igen | F10: Cserép alá – vízfelfogás, gurulós alátét | G10: SEO title / H1 / bevezető (másodlagos)
A11: 5 | B11: gurulós virágtartó | C11: 260 | D11: Laza | E11: Igen | F11: Cserép alá – vízfelfogás, gurulós alátét | G11: Kategórialeírás (természetes említés)
A12: 6 | B12: virágcserép alátét | C12: 140 | D12: Szoros | E12: Igen | F12: Cserép alá – vízfelfogás, gurulós alátét | G12: SEO title / H1 / bevezető (másodlagos)
A13: 7 | B13: virágcserép alátéttel | C13: 140 | D13: Szoros | E13: Igen | F13: Cserép alá – vízfelfogás, gurulós alátét | G13: Kategórialeírás (természetes említés)
A14: 8 | B14: műanyag cserépalátét | C14: 110 | D14: Szoros | E14: Igen | F14: Cserép alá – vízfelfogás, gurulós alátét | G14: SEO title / H1 / bevezető (másodlagos)
A15: 9 | B15: kerámia cserépalátét | C15: 90 | D15: Laza | E15: Nem | F15: Cserép alá – vízfelfogás, gurulós alátét | G15: Nem célozni külön oldallal (max. említés)
A16: 10 | B16: gurulós virágállvány | C16: 70 | D16: Laza | E16: Igen | F16: Cserép alá – vízfelfogás, gurulós alátét | G16: Kategórialeírás (természetes említés)
A17: 11 | B17: agyag cserépalátét | C17: 70 | D17: Laza | E17: Nem | F17: Cserép alá – vízfelfogás, gurulós alátét | G17: Nem célozni külön oldallal (max. említés)
A18: 12 | B18: virágcserép alátét 60 cm | C18: 50 | D18: Szoros | E18: Igen | F18: Cserép alá – vízfelfogás, gurulós alátét | G18: Kategórialeírás (természetes említés)
... A29: 23 | B29: virágcserép alátét méretek | C29: 10 | D29: Szoros | E29: Igen | F29: Cserép alá – vízfelfogás, gurulós alátét | G29: Leírás alsó része, GYIK vagy blog
B30: Összesen (érdemes rá oldal = Igen): | C30: =SUMIFS(C7:C29,E7:E29,"Igen")
A32: Termékek a jelenlegi kínálatból: 40 db (elsődleges + másodlagos hozzárendelés; egy termék több kategóriában is szerepelhet)
A33: # | B33: Termékkód | C33: Terméknév | D33: Hozzárendelés | E33: Illeszkedés | F33: Megjegyzés
A34: 1 | B34: GRO1049 | C34: Szögletes műanyag virágcserép alátét 16 x 16 cm | D34: Elsődleges | E34: Erős | F34: Szögletes cserépalátét
A35: 2 | B35: GRO1184 | C35: Szögletes műanyag virágcserép alátét 13,5 x 13,5 cm | D35: Elsődleges | E35: Erős | F35: Szögletes cserépalátét
A36: 3 | B36: GRO1185 | C36: Szögletes műanyag virágcserép alátét 14 x 14 cm | D36: Elsődleges | E36: Erős | F36: Szögletes cserépalátét
A37: 4 | B37: GRO1190 | C37: Szögletes műanyag virágcserép alátét 24 x 24 cm | D37: Elsődleges | E37: Erős | F37: Szögletes cserépalátét
A38: 5 | B38: GRO1262 | C38: Szögletes műanyag virágcserép alátét 25 x 25 cm | D38: Elsődleges | E38: Erős | F38: Szögletes cserépalátét
A39: 6 | B39: GRO1813 | C39: Szögletes műanyag virágcserép alátét 10,5 x 10,5 cm | D39: Elsődleges | E39: Erős | F39: Szögletes cserépalátét
A40: 7 | B40: GRO1814 | C40: Szögletes műanyag virágcserép alátét 19.5x19.5 | D40: Elsődleges | E40: Erős | F40: Szögletes cserépalátét
A41: 8 | B41: GRO2105 | C41: Szögletes műanyag virágcserép alátét 17.5x17.5 | D41: Elsődleges | E41: Erős | F41: Szögletes cserépalátét
A42: 9 | B42: GRO2106 | C42: Szögletes műanyag virágcserép alátét 20,5 x 20,5 cm | D42: Elsődleges | E42: Erős | F42: Szögletes cserépalátét
A43: 10 | B43: GRO3717 | C43: Kerek műanyag virágcserép alátét | D43: Elsődleges | E43: Erős | F43: Kerek cserépalátét
A44: 11 | B44: GRO4298 | C44: AC Infinity Víztartályos alátét 4 db 3,7 L (19 L szövetcseréphez) | D44: Elsődleges | E44: Laza | F44: Víztartályos (önöntöző) alátét szövetcseréphez
A45: 12 | B45: GRO4408 | C45: Cserépalátét univerzális tálca 72x50 cm | D45: Elsődleges | E45: Erős | F45: Univerzális alátéttálca
... A73: 40 | B73: GRO4616 | C73: Garland Mini tálca cserépalátét 23x17x6 cm | D73: Másodlagos | E73: Laza | F73: Garland Seed / Mini tálca – cserépalátétként is

Sheet 7 Tálca
A1: Műanyag tálca, árapály asztal – fő kulcsszó: „nagyméretű műanyag tálca”
A2: Felhasználási terület: Gyűjtőtálca termesztősátorba, árapály (ebb & flow) rendszer
A3: Megjegyzés: A „gyűjtőtálca”, „növénytálca”, „cserép tálca” kifejezésekre nincs mérhető keresés. A „tálcák” (1000) konyhai, a „csepptálca” (210) és a „kármentő tálca” (480) klíma / ipari. A „szaporító / palántanevelő tálca” a Palántanevelő ágé, a „mikrozöld tálca” a Mikrozöld termesztésé.
A4: Felvett releváns kulcsszavak: 21 (a Kulcsszótervező > 0 keresésű ötleteiből válogatva; a teljes nyers lista a CSV-ben)
A6: # | B6: Kulcsszó | C6: Havi keresés | D6: Kötődés a webshophoz | E6: Érdemes rá kategória/oldal? | F6: Felhasználási terület | G6: Javasolt felhasználás
A7: 1 | B7: nagyméretű műanyag tálca | C7: 140 | D7: Laza | E7: Igen | F7: Gyűjtőtálca termesztősátorba, árapály (ebb & flow) rendszer | G7: Kategórianév + H1 + SEO title (fő kulcsszó)
A8: 2 | B8: tálcák | C8: 1000 | D8: Laza | E8: Nem | F8: Gyűjtőtálca termesztősátorba, árapály (ebb & flow) rendszer | G8: Nem célozni külön oldallal (max. említés)
A9: 3 | B9: műanyag tálca | C9: 590 | D9: Laza | E9: Igen | F9: Gyűjtőtálca termesztősátorba, árapály (ebb & flow) rendszer | G9: SEO title / H1 / bevezető (másodlagos)
A10: 4 | B10: kármentő tálca | C10: 480 | D10: Laza | E10: Nem | F10: Gyűjtőtálca termesztősátorba, árapály (ebb & flow) rendszer | G10: Nem célozni külön oldallal (max. említés)
A11: 5 | B11: szaporító tálca | C11: 320 | D11: Laza | E11: Nem | F11: Gyűjtőtálca termesztősátorba, árapály (ebb & flow) rendszer | G11: Nem célozni külön oldallal (max. említés)
A12: 6 | B12: csepptálca | C12: 210 | D12: Laza | E12: Nem | F12: Gyűjtőtálca termesztősátorba, árapály (ebb & flow) rendszer | G12: Nem célozni külön oldallal (max. említés)
A13: 7 | B13: ebb and flow | C13: 70 | D13: Szoros | E13: Igen | F13: Gyűjtőtálca termesztősátorba, árapály (ebb & flow) rendszer | G13: SEO title / H1 / bevezető (másodlagos)
A14: 8 | B14: műanyag csepegtető tálca | C14: 70 | D14: Laza | E14: Igen | F14: Gyűjtőtálca termesztősátorba, árapály (ebb & flow) rendszer | G14: Kategórialeírás (természetes említés)
A15: 9 | B15: árapály asztal | C15: 50 | D15: Szoros | E15: Igen | F15: Gyűjtőtálca termesztősátorba, árapály (ebb & flow) rendszer | G15: SEO title / H1 / bevezető (másodlagos)
A16: 10 | B16: műanyag kármentő tálca | C16: 50 | D16: Laza | E16: Igen | F16: Gyűjtőtálca termesztősátorba, árapály (ebb & flow) rendszer | G16: Kategórialeírás (természetes említés)
A17: 11 | B17: műanyag tálca obi | C17: 50 | D17: Nincs (áruházi / nem vásárlási szándék) | E17: Nem – kizárandó | F17: Gyűjtőtálca termesztősátorba, árapály (ebb & flow) rendszer | G17: Nem használni (áruházi/nem vásárlási szándék)
A18: 12 | B18: nagy műanyag tálca | C18: 40 | D18: Laza | E18: Igen | F18: Gyűjtőtálca termesztősátorba, árapály (ebb & flow) rendszer | G18: Kategórialeírás (természetes említés)
... A27: 21 | B27: kerti tálca | C27: 10 | D27: Szoros | E27: Igen | F27: Gyűjtőtálca termesztősátorba, árapály (ebb & flow) rendszer | G27: Kategórialeírás (természetes említés)
B28: Összesen (érdemes rá oldal = Igen): | C28: =SUMIFS(C7:C27,E7:E27,"Igen")
A30: Termékek a jelenlegi kínálatból: 36 db (elsődleges + másodlagos hozzárendelés; egy termék több kategóriában is szerepelhet)
A31: # | B31: Termékkód | C31: Terméknév | D31: Hozzárendelés | E31: Illeszkedés | F31: Megjegyzés
A32: 1 | B32: GRO0054 | C32: Dán tálca apály-dagály alátét 106 x 33 cm árasztásos rendszerhez | D32: Elsődleges | E32: Erős | F32: Dán tálca – apály-dagály (árapály) rendszer
A33: 2 | B33: GRO0056 | C33: Dán tálca apály-dagály alátét 106 x 102 cm árasztásos rendszerhez | D33: Elsődleges | E33: Erős | F33: Dán tálca – apály-dagály (árapály) rendszer
A34: 3 | B34: GRO0057 | C34: Dán tálca apály-dagály alátét 106 x 202 cm árasztásos rendszerhez | D34: Elsődleges | E34: Erős | F34: Dán tálca – apály-dagály (árapály) rendszer
A35: 4 | B35: GRO1417 | C35: Dán tálca apály-dagály alátét 106 x 63 cm árasztásos rendszerhez | D35: Elsődleges | E35: Erős | F35: Dán tálca – apály-dagály (árapály) rendszer
A36: 5 | B36: GRO1462 | C36: Garland tálca (12 cm magas) M | D36: Elsődleges | E36: Erős | F36: Garland tálca (5–15 cm perem)
A37: 6 | B37: GRO1463 | C37: Garland Titan tálca 100 x 55 x 15 cm, 65 literes, újrahasznosított polipropilén | D37: Elsődleges | E37: Erős | F37: Garland tálca (5–15 cm perem)
A38: 7 | B38: GRO1817 | C38: Dán tálca kiegészítő leeresztő szűrő a 106 x 202 cm-es apály-dagály tálcához | D38: Elsődleges | E38: Laza | F38: Dán tálca kiegészítő
A39: 8 | B39: GRO1906 | C39: Garland Square négyzetes tálca 59 x 59 x 7 cm (M), fröccsöntött polipropilén | D39: Elsődleges | E39: Erős | F39: Garland tálca (5–15 cm perem)
A40: 9 | B40: GRO1907 | C40: Garland Giant tálca 110 x 55 x 5 cm, hosszúkás, fröccsöntött polipropilén | D40: Elsődleges | E40: Erős | F40: Garland tálca (5–15 cm perem)
A41: 10 | B41: GRO1908 | C41: Garland tálca (12 cm magas) L | D41: Elsődleges | E41: Erős | F41: Garland tálca (5–15 cm perem)
A42: 11 | B42: GRO1909 | C42: Garland tálca 5 cm magas peremmel, XS méret, fröccsöntött polipropilén | D42: Elsődleges | E42: Erős | F42: Garland tálca (5–15 cm perem)
