Workbook

Sheet Összefoglaló
A1: babylon-grow.eu – Aktív szénszűrő, légtechnika kulcsszókutatás (Google Ads Kulcsszótervező, HU, magyar, 12 hó átlag)
A2: Forrás: Babylon Adwords fiók (867-850-6485) Kulcsszótervező (Windsor.ai-on át), lekérdezve: 2026-10-15/16. Hely: Magyarország, nyelv: magyar, hálózat: Google Keresés. A számok kerekített lépcsős havi átlagok. Termékek: élő kínálat = Google Shopping-feed, elmúlt 30 nap (1525 termék).
A4: Kategória (menünév) | B4: Fő kulcsszó | C4: Fő kulcsszó havi | D4: Klaszter összesen (érdemes = Igen) | E4: Kötődés a webshophoz | F4: Érdemes rá kategória? | G4: Felhasználási terület | H4: Javasolt hely az új fában
A5: Csőventilátor, elszívó ventilátor | B5: csőventilátor | C5: =SUMIFS('Összes kulcsszó'!$E:$E,'Összes kulcsszó'!$A:$A,A5,'Összes kulcsszó'!$C:$C,B5) | D5: =SUMIFS('Összes kulcsszó'!$E:$E,'Összes kulcsszó'!$A:$A,A5,'Összes kulcsszó'!$G:$G,"Igen") | E5: Szoros | F5: Igen | G5: Elszívás / befúvás a termesztőtérben – centrifugális, kevert áramlású és EC csőventilátor | H5: 2. szint – a sandbox-név jó; alá kerül a „Ventilátor-vezérlő, termosztát” (3. szint)
A6: Aktív szénszűrő, előszűrő | B6: aktív szénszűrő | C6: =SUMIFS('Összes kulcsszó'!$E:$E,'Összes kulcsszó'!$A:$A,A6,'Összes kulcsszó'!$C:$C,B6) | D6: =SUMIFS('Összes kulcsszó'!$E:$E,'Összes kulcsszó'!$A:$A,A6,'Összes kulcsszó'!$G:$G,"Igen") | E6: Szoros | F6: Igen | G6: Szagszűrés a termesztőtérből elszívott levegőből – aktív szénszűrő, előszűrő, utántöltő szén | H6: 2. szint (sandbox: „Aktív Szénszűrő csőventilátorhoz”) – a „csőventilátorhoz” toldat a H1 / leírás része legyen, ne a menünévé
A7: Légtechnikai cső, idom, bilincs | B7: légtechnika cső | C7: =SUMIFS('Összes kulcsszó'!$E:$E,'Összes kulcsszó'!$A:$A,A7,'Összes kulcsszó'!$C:$C,B7) | D7: =SUMIFS('Összes kulcsszó'!$E:$E,'Összes kulcsszó'!$A:$A,A7,'Összes kulcsszó'!$G:$G,"Igen") | E7: Szoros | F7: Igen | G7: Flexibilis légcsatorna (Aluflex, Sonoflex, Combiflex), idom, bővítő / szűkítő, csőtoldó, visszacsapó szelep, bilincs, ragasztószalag, ventilátor-hangtompító | H7: 2. szint – a legtöbb termékes alkategória; 3. szintű szűrő: cső / idom / bilincs / szalag / hangtompító
A8: Szagsemlegesítő, ózongenerátor | B8: szagsemlegesítő | C8: =SUMIFS('Összes kulcsszó'!$E:$E,'Összes kulcsszó'!$A:$A,A8,'Összes kulcsszó'!$C:$C,B8) | D8: =SUMIFS('Összes kulcsszó'!$E:$E,'Összes kulcsszó'!$A:$A,A8,'Összes kulcsszó'!$G:$G,"Igen") | E8: Szoros | F8: Igen | G8: Szagkezelés szénszűrő mellett / helyett – ONA gél, tömb, spray, légcsatornába építhető ONA szűrő, ózongenerátor | H8: 2. szint – a sandbox-név jó
A9: Keringető ventilátor | B9: padlóventilátor | C9: =SUMIFS('Összes kulcsszó'!$E:$E,'Összes kulcsszó'!$A:$A,A9,'Összes kulcsszó'!$C:$C,B9) | D9: =SUMIFS('Összes kulcsszó'!$E:$E,'Összes kulcsszó'!$A:$A,A9,'Összes kulcsszó'!$G:$G,"Igen") | E9: Szoros | F9: Igen | G9: Légmozgatás a növények között – csíptetős (Monkey Fan, Cloudray), padló-, álló- és fali ventilátor | H9: 2. szint (sandbox: „Keringető ventilátor growboxba”) – név marad, a „growboxba” a H1-be / leírásba
A10: Páramentesítő | B10: páramentesítő | C10: =SUMIFS('Összes kulcsszó'!$E:$E,'Összes kulcsszó'!$A:$A,A10,'Összes kulcsszó'!$C:$C,B10) | D10: =SUMIFS('Összes kulcsszó'!$E:$E,'Összes kulcsszó'!$A:$A,A10,'Összes kulcsszó'!$G:$G,"Igen") | E10: Szoros | F10: Igen | G10: Páratartalom csökkentése a termesztőtérben, szárításnál – kompresszoros / Peltier páramentesítő | H10: 3. szint a „Klímaszabályozás, párásítás, párátlanítás” alatt
A11: Párásító | B11: párásító | C11: =SUMIFS('Összes kulcsszó'!$E:$E,'Összes kulcsszó'!$A:$A,A11,'Összes kulcsszó'!$C:$C,B11) | D11: =SUMIFS('Összes kulcsszó'!$E:$E,'Összes kulcsszó'!$A:$A,A11,'Összes kulcsszó'!$G:$G,"Igen") | E11: Szoros | F11: Igen | G11: Páratartalom növelése a termesztőtérben – ultrahangos / hideg párásító, ködgenerátor, vezérlő | H11: 3. szint a „Klímaszabályozás, párásítás, párátlanítás” alatt
A12: Klímavezérlő: ventilátor-szabályzó, termosztát, higrosztát | B12: ventilátor fordulatszám szabályzó | C12: =SUMIFS('Összes kulcsszó'!$E:$E,'Összes kulcsszó'!$A:$A,A12,'Összes kulcsszó'!$C:$C,B12) | D12: =SUMIFS('Összes kulcsszó'!$E:$E,'Összes kulcsszó'!$A:$A,A12,'Összes kulcsszó'!$G:$G,"Igen") | E12: Szoros | F12: Igen | G12: Csőventilátor fordulatszám-, hőmérséklet-, páratartalom- és nyomásszabályzása; környezeti vezérlő (AC Infinity, GSE, OptiClimate) | H12: 2. szint – önálló kategória: ventilátorok, párásítók, fűtés vezérlése egy helyen (környezetvezérlő)
A13: Hő- és páratartalom-mérő | B13: páratartalom mérő | C13: =SUMIFS('Összes kulcsszó'!$E:$E,'Összes kulcsszó'!$A:$A,A13,'Összes kulcsszó'!$C:$C,B13) | D13: =SUMIFS('Összes kulcsszó'!$E:$E,'Összes kulcsszó'!$A:$A,A13,'Összes kulcsszó'!$G:$G,"Igen") | E13: Szoros | F13: Igen | G13: Hőmérséklet és relatív páratartalom mérése – digitális thermo-higrométer | H13: 3. szint a Klíma alatt VAGY a Mérőműszer ágban (pH / EC mellett) – egy céloldal, a másik helyen link
A14: CO2-pótlás, CO2-mérő | B14: co2 mérő | C14: =SUMIFS('Összes kulcsszó'!$E:$E,'Összes kulcsszó'!$A:$A,A14,'Összes kulcsszó'!$C:$C,B14) | D14: =SUMIFS('Összes kulcsszó'!$E:$E,'Összes kulcsszó'!$A:$A,A14,'Összes kulcsszó'!$G:$G,"Igen") | E14: Szoros | F14: Igen | G14: CO2-szint emelése és mérése – CO2 zsák, tabletta, palack + reduktor, propános CO2 generátor, CO2 érzékelő / szabályzó | H14: 2. szint (sandbox: „CO2”) – a puszta „CO2” név túl általános
A16: Jelmagyarázat
A17: Szoros kötődés · érdemes: Igen
A18: Laza kötődés · érdemes: Igen
A19: Laza kötődés · érdemes: Nem
A20: Nincs (áruházi / nem vásárlási szándék) kötődés · érdemes: Nem – kizárandó
A22: Megjegyzés: a klaszter-összeg átfedéseket tartalmazhat (pl. elírt és ékezet nélküli változatok, amelyeket a Google külön sorban is mutat).
A23: Módszer: csak a főkategória neve („Aktív szénszűrő, légtechnika”) adott; az alkategóriák a termékek funkciójából (elszívás, szagszűrés, csövezés, keringetés, páratartalom, vezérlés, CO2) és a keresési szándékból épülnek, lapos (2 szintű) szerkezetben.
A24: Fő megállapítások: a „légtechnika” (1300) és a „légtechnika cső” (880) erősebb, mint a „légcsatorna” (320) → a csőkategória fő szava „légtechnika cső”. A legnagyobb termékkulcsszavak a klímán vannak (páramentesítő 9900, párásító 5400, páratartalom mérő 1600) → önálló 2. szintű kategóriák.
A25: A „légtechnikai bolt” (720) / „légtechnika webáruház” (110) bolt-keresés – a főkategória title-jében érdemes kiszolgálni.
A26: A nagy általános szavak (ventilátor 18100, légtisztító 5400, szellőzés 2900, flexibilis cső 2400, visszacsapó szelep 2400, hangtompító 880) más szándékúak – LN.

Sheet Kategóriaszerkezet-ajánlás
A1: Kategóriaszerkezet-ajánlás – Aktív szénszűrő, légtechnika (csak a főkategória neve + termékkínálat + kulcsszóadat alapján)
A2: A korábbi és a sandbox alkategória-neveket és -szerkezetet NEM vettük figyelembe. Kiindulás: a főkategória neve, az élő termékkínálat (Google Shopping-feed, elmúlt 30 nap) és a Kulcsszótervező adatai. Termékszám = élő termékek, elsődleges + másodlagos hozzárendelés.
A4: Szint | B4: Javasolt kategórianév (menünév) | C4: Szülőkategória | D4: Fő kulcsszó | E4: Fő kulcsszó havi | F4: Klaszter összesen (érdemes = Igen) | G4: Kulcsszó-kötődés | H4: Termékek száma | I4: Típus | J4: Indoklás
A5: 1 | B5: Aktív szénszűrő, légtechnika | C5: – | D5: légtechnika | E5: 1300 | G5: Erősen kapcsolódik | H5: 353 | I5: Főkategória | J5: Légtechnika 1300 (+ légtechnikai bolt 720) – a főkategória H1-je: „Légtechnika, aktív szénszűrő, csőventilátor”.
A6: 2 | B6: Csőventilátor, elszívó ventilátor | C6: Aktív szénszűrő, légtechnika | D6: csőventilátor | E6: 1000 | F6: =SUMIFS('Összes kulcsszó'!$E:$E,'Összes kulcsszó'!$A:$A,"Csőventilátor, elszívó ventilátor",'Összes kulcsszó'!$G:$G,"Igen") | G6: Erősen kapcsolódik | H6: 84 | I6: Önálló kategória | J6: Csőventilátor 1000, elszívó ventilátor 1900 (vegyes); átmérő / EC = szűrő.
A7: 2 | B7: Aktív szénszűrő, előszűrő | C7: Aktív szénszűrő, légtechnika | D7: aktív szénszűrő | E7: 210 | F7: =SUMIFS('Összes kulcsszó'!$E:$E,'Összes kulcsszó'!$A:$A,"Aktív szénszűrő, előszűrő",'Összes kulcsszó'!$G:$G,"Igen") | G7: Erősen kapcsolódik | H7: 64 | I7: Önálló kategória | J7: Aktív szénszűrő 210 – a főkategória névadó terméke.
A8: 2 | B8: Légtechnikai cső, idom, bilincs | C8: Aktív szénszűrő, légtechnika | D8: légtechnika cső | E8: 880 | F8: =SUMIFS('Összes kulcsszó'!$E:$E,'Összes kulcsszó'!$A:$A,"Légtechnikai cső, idom, bilincs",'Összes kulcsszó'!$G:$G,"Igen") | G8: Erősen kapcsolódik | H8: 114 | I8: Önálló kategória | J8: Légtechnika cső 880 – a legtöbb termék (~100 élő).
A9: 2 | B9: Szagsemlegesítő, ózongenerátor | C9: Aktív szénszűrő, légtechnika | D9: szagsemlegesítő | E9: 260 | F9: =SUMIFS('Összes kulcsszó'!$E:$E,'Összes kulcsszó'!$A:$A,"Szagsemlegesítő, ózongenerátor",'Összes kulcsszó'!$G:$G,"Igen") | G9: Erősen kapcsolódik | H9: 49 | I9: Önálló kategória | J9: Szagsemlegesítő 260; ózongenerátor 6600, de 1 termék.
A10: 2 | B10: Keringető ventilátor | C10: Aktív szénszűrő, légtechnika | D10: padlóventilátor | E10: 1300 | F10: =SUMIFS('Összes kulcsszó'!$E:$E,'Összes kulcsszó'!$A:$A,"Keringető ventilátor",'Összes kulcsszó'!$G:$G,"Igen") | G10: Erősen kapcsolódik | H10: 15 | I10: Önálló kategória | J10: Padlóventilátor 1300, fali ventilátor 880 (laza).
A11: 2 | B11: Páramentesítő | C11: Aktív szénszűrő, légtechnika | D11: páramentesítő | E11: 9900 | F11: =SUMIFS('Összes kulcsszó'!$E:$E,'Összes kulcsszó'!$A:$A,"Páramentesítő",'Összes kulcsszó'!$G:$G,"Igen") | G11: Erősen kapcsolódik | H11: 5 | I11: Önálló kategória | J11: Páramentesítő 9900 – az ág legnagyobb kulcsszava.
A12: 2 | B12: Párásító | C12: Aktív szénszűrő, légtechnika | D12: párásító | E12: 5400 | F12: =SUMIFS('Összes kulcsszó'!$E:$E,'Összes kulcsszó'!$A:$A,"Párásító",'Összes kulcsszó'!$G:$G,"Igen") | G12: Erősen kapcsolódik | H12: 8 | I12: Önálló kategória | J12: Párásító 5400, ultrahangos párásító 1000.
A13: 2 | B13: Klímavezérlő: ventilátor-szabályzó, termosztát, higrosztát | C13: Aktív szénszűrő, légtechnika | D13: ventilátor fordulatszám szabályzó | E13: 110 | F13: =SUMIFS('Összes kulcsszó'!$E:$E,'Összes kulcsszó'!$A:$A,"Klímavezérlő: ventilátor-szabályzó, termosztát, higrosztát",'Összes kulcsszó'!$G:$G,"Igen") | G13: Erősen kapcsolódik | H13: 41 | I13: Önálló kategória | J13: Ventilátor fordulatszám szabályzó 110, higrosztát 70, páratartalom szabályzó 70.
A14: 2 | B14: Hő- és páratartalom-mérő | C14: Aktív szénszűrő, légtechnika | D14: páratartalom mérő | E14: 1600 | F14: =SUMIFS('Összes kulcsszó'!$E:$E,'Összes kulcsszó'!$A:$A,"Hő- és páratartalom-mérő",'Összes kulcsszó'!$G:$G,"Igen") | G14: Erősen kapcsolódik | H14: 4 | I14: Önálló kategória | J14: Páratartalom mérő 1600 – vagy a Mérőműszer ágban (egy céloldal).
A15: 2 | B15: CO2-pótlás, CO2-mérő | C15: Aktív szénszűrő, légtechnika | D15: co2 mérő | E15: 210 | F15: =SUMIFS('Összes kulcsszó'!$E:$E,'Összes kulcsszó'!$A:$A,"CO2-pótlás, CO2-mérő",'Összes kulcsszó'!$G:$G,"Igen") | G15: Erősen kapcsolódik | H15: 15 | I15: Önálló kategória | J15: Co2 mérő 210, co2 érzékelő 170.
A17: Ami NE legyen önálló kategória
A18: Téma | B18: Kulcsszó | C18: Havi keresés | D18: Javaslat
A19: Klíma gyűjtőkategória (párásító + páramentesítő + mérő egy ág alatt) | B19: páramentesítő | C19: 9900 | D19: A páramentesítő (9900) és a párásító (5400) erős önálló kulcsszó – közvetlenül 2. szinten jobb.
A20: Ózongenerátor (külön kategória) | B20: ózongenerátor | C20: 6600 | D20: Nagy kereslet, de 1 termék – szűrő / H2, bővítés esetén saját kategória.
A21: Hangtompító (külön kategória) | B21: hangtompító | C21: 880 | D21: A „hangtompító” (880) autós kipufogó – a ventilátor-hangtompító a Légtechnikai cső alatt szűrő.
A22: Lakás-szellőztetés, légtisztító | B22: légtisztító | C22: 5400 | D22: Épületgépészet / háztartás – nem a mi termékünk.
A23: Fürdőszobai elszívó | B23: fürdőszobai elszívó | C23: 390 | D23: Nem a mi termékünk.

Sheet Termékkínálat
A1: Termékkínálat – termék–kategória hozzárendelés
A2: ÉLŐ KÍNÁLAT ALAPJÁN (2026-10-16): csak az elmúlt 30 napban a Babylon Google Shopping-feedben szereplő termékek (1525) kaptak kategóriát – ez az éles oldal aktuális kínálata. A most nem élő termékek „Nem aktív” jelöléssel a lap végén vannak.
A3: A szerkezet csak a főkategória nevéből, a termékek típusából és a keresési szándékból készült – a korábbi és a sandbox alkategóriák figyelmen kívül.
A4: Beépített szabályzós csőventilátorok elsődlegesen a Csőventilátorba, másodlagosan a Klímavezérlőbe kerültek.
A6: Termékkód | B6: Terméknév | C6: Elsődleges javasolt kategória | D6: További kategóriák | E6: Illeszkedés | F6: Utoljára a Google Shopping-feedben | G6: Megjegyzés
A7: GRO1044 | B7: Can Filters Can-Lite 1500 aktív szénszűrő acél házzal, 1500 m3/h, 250 mm szűrővég | C7: Aktív szénszűrő, előszűrő | E7: Erős | F7: az elmúlt 30 napban | G7: Aktív szénszűrő (Can-Lite, Can Original, Can-Inline, Prima Klima, DF16, AC Infinity…)
A8: GRO1075 | B8: Can Filters Can-Lite 2500 aktív szénszűrő acél házzal, 2500 m3/h, 250 mm szűrővég | C8: Aktív szénszűrő, előszűrő | E8: Erős | F8: az elmúlt 30 napban | G8: Aktív szénszűrő (Can-Lite, Can Original, Can-Inline, Prima Klima, DF16, AC Infinity…)
A9: GRO1077 | B9: Can Filters Can-Lite 1000 aktív szénszűrő acél házzal, 1000 m3/h, 250 mm szűrővég | C9: Aktív szénszűrő, előszűrő | E9: Erős | F9: az elmúlt 30 napban | G9: Aktív szénszűrő (Can-Lite, Can Original, Can-Inline, Prima Klima, DF16, AC Infinity…)
A10: GRO1078 | B10: Can Filters Can-Lite 600 aktív szénszűrő acél házzal, 600 m3/h, 150 mm szűrővég | C10: Aktív szénszűrő, előszűrő | E10: Erős | F10: az elmúlt 30 napban | G10: Aktív szénszűrő (Can-Lite, Can Original, Can-Inline, Prima Klima, DF16, AC Infinity…)
A11: GRO1079 | B11: Can Filters Can-Lite 300 aktív szénszűrő műanyag házzal, 300 m3/h | C11: Aktív szénszűrő, előszűrő | E11: Erős | F11: az elmúlt 30 napban | G11: Aktív szénszűrő (Can-Lite, Can Original, Can-Inline, Prima Klima, DF16, AC Infinity…)
A12: GRO1080 | B12: Can Filters Can-Lite 150 aktív szénszűrő műanyag házzal, 150 m3/h | C12: Aktív szénszűrő, előszűrő | E12: Erős | F12: az elmúlt 30 napban | G12: Aktív szénszűrő (Can-Lite, Can Original, Can-Inline, Prima Klima, DF16, AC Infinity…)
A13: GRO1081 | B13: Can Filters Can-Lite 425 aktív szénszűrő műanyag házzal, 425 m3/h | C13: Aktív szénszűrő, előszűrő | E13: Erős | F13: az elmúlt 30 napban | G13: Aktív szénszűrő (Can-Lite, Can Original, Can-Inline, Prima Klima, DF16, AC Infinity…)
A14: GRO1663 | B14: Can Filters Can-Lite 3000 aktív szénszűrő acél házzal, 3000 m3/h, 315 mm szűrővég | C14: Aktív szénszűrő, előszűrő | E14: Erős | F14: az elmúlt 30 napban | G14: Aktív szénszűrő (Can-Lite, Can Original, Can-Inline, Prima Klima, DF16, AC Infinity…)
A15: GRO2182 | B15: Can Filters Can-Lite műanyag szűrővég 100 mm, Can-Lite 150, 300 és 425 szénszűrőhöz | C15: Aktív szénszűrő, előszűrő | E15: Erős | F15: az elmúlt 30 napban | G15: Aktív szénszűrő (Can-Lite, Can Original, Can-Inline, Prima Klima, DF16, AC Infinity…)
A16: GRO2220 | B16: Can Filters Can-Lite műanyag szűrővég 125 mm, Can-Lite 150, 300 és 425 szénszűrőhöz | C16: Aktív szénszűrő, előszűrő | E16: Erős | F16: az elmúlt 30 napban | G16: Aktív szénszűrő (Can-Lite, Can Original, Can-Inline, Prima Klima, DF16, AC Infinity…)
A17: GRO2921 | B17: Can Filters Can-Lite 800 aktív szénszűrő acél házzal, 800 m3/h, 200 mm szűrővég | C17: Aktív szénszűrő, előszűrő | E17: Erős | F17: az elmúlt 30 napban | G17: Aktív szénszűrő (Can-Lite, Can Original, Can-Inline, Prima Klima, DF16, AC Infinity…)
A18: GRO3211 | B18: CAN Original aktív szénszűrő CF 2100 m3/h, 250 mm szűrővég, pelletált szénnel | C18: Aktív szénszűrő, előszűrő | E18: Erős | F18: az elmúlt 30 napban | G18: Előszűrő, utántöltő szénpellet
... A66: GRO4216 | B66: Prima Klima Industry Line K1612 2700 m3/h Pre Filter | C66: Aktív szénszűrő, előszűrő | E66: Erős | F66: az elmúlt 30 napban | G66: Előszűrő, utántöltő szénpellet
A67: GRO4303 | B67: AC Infinity PRO légszűrő rendszer AI+WiFi 150 mm | C67: Aktív szénszűrő, előszűrő | D67: Csőventilátor, elszívó ventilátor | E67: Erős | F67: az elmúlt 30 napban | G67: AC Infinity légszűrő rendszer (ventilátor + szénszűrő)
A68: GRO4322 | B68: AC Infinity szénszűrő Australian Charcoal d: 100 mm 357 m3/h | C68: Aktív szénszűrő, előszűrő | E68: Erős | F68: az elmúlt 30 napban | G68: Aktív szénszűrő (Can-Lite, Can Original, Can-Inline, Prima Klima, DF16, AC Infinity…)
A69: GRO4323 | B69: AC Infinity szénszűrő Australian Charcoal d: 150 mm 700 m3/h | C69: Aktív szénszűrő, előszűrő | E69: Erős | F69: az elmúlt 30 napban | G69: Aktív szénszűrő (Can-Lite, Can Original, Can-Inline, Prima Klima, DF16, AC Infinity…)
A70: GRO4342 | B70: AC Infinity szénszűrő Australian Charcoal d: 200 mm 1308 m3/h | C70: Aktív szénszűrő, előszűrő | E70: Erős | F70: az elmúlt 30 napban | G70: Aktív szénszűrő (Can-Lite, Can Original, Can-Inline, Prima Klima, DF16, AC Infinity…)
A71: GRO2490 | B71: ExHale Original CO2 termelő zsák micéliummal, termesztősátorba, 6 hónapig | C71: CO2-pótlás, CO2-mérő | E71: Erős | F71: az elmúlt 30 napban | G71: CO2 zsák, CO2 termelő doboz, tabletta
A72: GRO3563 | B72: Pro-Leaf CO2 érzékelő és digitális szabályzó | C72: CO2-pótlás, CO2-mérő | D72: Klímavezérlő: ventilátor-szabályzó, termosztát, higrosztát | E72: Erős | F72: az elmúlt 30 napban | G72: CO2 érzékelő, szabályzó
A73: GRO3734 | B73: SGC CO2 pára-, hőmérséklet- és fényszenzor | C73: CO2-pótlás, CO2-mérő | D73: Klímavezérlő: ventilátor-szabályzó, termosztát, higrosztát | E73: Erős | F73: az elmúlt 30 napban | G73: CO2 érzékelő, szabályzó
A74: GRO3790 | B74: Smart CO2 termelő zsák | C74: CO2-pótlás, CO2-mérő | E74: Erős | F74: az elmúlt 30 napban | G74: CO2 zsák, CO2 termelő doboz, tabletta
A75: GRO3811 | B75: CO2 reduktor - nyomásmérő és szabályozó szelep | C75: CO2-pótlás, CO2-mérő | E75: Erős | F75: az elmúlt 30 napban | G75: CO2 palack, adapter, reduktor
A76: GRO3902 | B76: Exhale CO2 zsák XL | C76: CO2-pótlás, CO2-mérő | E76: Erős | F76: az elmúlt 30 napban | G76: CO2 zsák, CO2 termelő doboz, tabletta
A77: GRO3903 | B77: CO2 termelő doboz | C77: CO2-pótlás, CO2-mérő | E77: Erős | F77: az elmúlt 30 napban | G77: CO2 zsák, CO2 termelő doboz, tabletta
A78: GRO4095 | B78: CO2 tabletta | C78: CO2-pótlás, CO2-mérő | E78: Erős | F78: az elmúlt 30 napban | G78: CO2 zsák, CO2 termelő doboz, tabletta
A79: GRO4096 | B79: CO2 tabletta | C79: CO2-pótlás, CO2-mérő | E79: Erős | F79: az elmúlt 30 napban | G79: CO2 zsák, CO2 termelő doboz, tabletta
A80: GRO4160 | B80: GrowBro CO2 palack | C80: CO2-pótlás, CO2-mérő | E80: Erős | F80: az elmúlt 30 napban | G80: CO2 palack, adapter, reduktor
A81: GRO4162 | B81: Autopilot Co2 generátor propán gázzal 4KW | C81: CO2-pótlás, CO2-mérő | E81: Erős | F81: az elmúlt 30 napban | G81: CO2 generátor (propán)
A82: GRO4163 | B82: Autopilot Co2 generátor propán gázzal 8KW | C82: CO2-pótlás, CO2-mérő | E82: Erős | F82: az elmúlt 30 napban | G82: CO2 generátor (propán)
A83: GRO4247 | B83: GrowBro CO2 adapter | C83: CO2-pótlás, CO2-mérő | E83: Erős | F83: az elmúlt 30 napban | G83: CO2 palack, adapter, reduktor
A84: GRO4340 | B84: AC Infinity Controller AI+ CO2 + fényérzékelő | C84: CO2-pótlás, CO2-mérő | D84: Klímavezérlő: ventilátor-szabályzó, termosztát, higrosztát | E84: Erős | F84: az elmúlt 30 napban | G84: CO2 érzékelő, szabályzó
A85: GRO0346 | B85: Can-Fan RK 250 centrifugális csőventilátor 250 mm, 830 m3/h | C85: Csőventilátor, elszívó ventilátor | E85: Erős | F85: az elmúlt 30 napban | G85: Csőventilátor (Can-Fan, Vents, Prima Klima, AC Infinity, Garden Highpro, DF16)
A86: GRO0776 | B86: Vents 100 VKO csőbe szerelhető axiális ventilátor 100 mm, 105 m3/h | C86: Csőventilátor, elszívó ventilátor | E86: Erős | F86: az elmúlt 30 napban | G86: Csőventilátor (Can-Fan, Vents, Prima Klima, AC Infinity, Garden Highpro, DF16)
A87: GRO0777 | B87: Vents 125 VKO csőbe szerelhető axiális ventilátor 125 mm, 185 m3/h | C87: Csőventilátor, elszívó ventilátor | E87: Erős | F87: az elmúlt 30 napban | G87: Csőventilátor (Can-Fan, Vents, Prima Klima, AC Infinity, Garden Highpro, DF16)
A88: GRO0778 | B88: Vents 150 VKO csőbe szerelhető axiális ventilátor 150 mm, 298 m3/h | C88: Csőventilátor, elszívó ventilátor | E88: Erős | F88: az elmúlt 30 napban | G88: Csőventilátor (Can-Fan, Vents, Prima Klima, AC Infinity, Garden Highpro, DF16)
...

Sheet Bővítés – rokon területek
A1: Kapcsolódó területek (Kulcsszótervező, HU, 12 hó átlag)
A2: Más szándékú vagy nem kínált témák, bővítési lehetőségek.
A4: Terület | B4: Javaslat | C4: Releváns keresés (Szoros+Laza)
A5: Háztartási ventilátor (álló, asztali, torony) | B5: Nagy volumen, de nem growshop-termék – csak kínálatbővítés esetén | C5: =SUMIFS(C14:C30,A14:A30,A5,E14:E30,"<>Nem")
A6: Fürdőszobai / konyhai elszívó | B6: Nem a mi termékünk | C6: =SUMIFS(C14:C30,A14:A30,A6,E14:E30,"<>Nem")
A7: Konyhai páraelszívó szénszűrője | B7: Nem a mi termékünk | C7: =SUMIFS(C14:C30,A14:A30,A7,E14:E30,"<>Nem")
A8: Ózongenerátor-kínálat bővítése | B8: Erős kereslet (6600) – kínálatbővítés esetén saját 3. szintű kategória | C8: =SUMIFS(C14:C30,A14:A30,A8,E14:E30,"<>Nem")
A9: Lakás-szellőztetés, légtisztító | B9: Háztartási / épületgépészeti szándék – nem a mi termékünk | C9: =SUMIFS(C14:C30,A14:A30,A9,E14:E30,"<>Nem")
A10: Szobatermosztát | B10: Fűtéstechnika – nem a mi termékünk | C10: =SUMIFS(C14:C30,A14:A30,A10,E14:E30,"<>Nem")
A13: Terület | B13: Kulcsszó | C13: Havi keresés | D13: Kötődés a webshophoz | E13: Érdemes rá oldal? | F13: Javasolt felhasználás
A14: Háztartási ventilátor (álló, asztali, torony) | B14: ventilátor | C14: 18100 | D14: Laza | E14: Igen | F14: Nagy volumen, de nem growshop-termék – csak kínálatbővítés esetén
A15: Háztartási ventilátor (álló, asztali, torony) | B15: álló ventilátor | C15: 4400 | D15: Laza | E15: Igen | F15: Nagy volumen, de nem growshop-termék – csak kínálatbővítés esetén
A16: Háztartási ventilátor (álló, asztali, torony) | B16: asztali ventilátor | C16: 2400 | D16: Laza | E16: Igen | F16: Nagy volumen, de nem growshop-termék – csak kínálatbővítés esetén
A17: Fürdőszobai / konyhai elszívó | B17: fürdőszobai elszívó | C17: 390 | D17: Laza | E17: Nem | F17: Nem a mi termékünk
A18: Fürdőszobai / konyhai elszívó | B18: wc elszívó ventilátor | C18: 260 | D18: Laza | E18: Nem | F18: Nem a mi termékünk
A19: Fürdőszobai / konyhai elszívó | B19: konyhai elszívó ventilátor | C19: 210 | D19: Laza | E19: Nem | F19: Nem a mi termékünk
A20: Konyhai páraelszívó szénszűrője | B20: szénszűrős páraelszívó | C20: 390 | D20: Laza | E20: Nem | F20: Nem a mi termékünk
A21: Konyhai páraelszívó szénszűrője | B21: páraelszívó szénszűrő | C21: 170 | D21: Laza | E21: Nem | F21: Nem a mi termékünk
A22: Ózongenerátor-kínálat bővítése | B22: ózongenerátor | C22: 6600 | D22: Szoros | E22: Igen | F22: Erős kereslet (6600) – kínálatbővítés esetén saját 3. szintű kategória
A23: Ózongenerátor-kínálat bővítése | B23: ozon generátor | C23: 1000 | D23: Szoros | E23: Igen | F23: Erős kereslet (6600) – kínálatbővítés esetén saját 3. szintű kategória
A24: Ózongenerátor-kínálat bővítése | B24: ózongenerátor fertőtlenítés | C24: 590 | D24: Laza | E24: Igen | F24: Erős kereslet (6600) – kínálatbővítés esetén saját 3. szintű kategória
A25: Lakás-szellőztetés, légtisztító | B25: légtisztító | C25: 5400 | D25: Laza | E25: Nem | F25: Háztartási / épületgépészeti szándék – nem a mi termékünk
... A30: Szobatermosztát | B30: konnektoros termosztát | C30: 110 | D30: Laza | E30: Igen | F30: Fűtéstechnika – nem a mi termékünk

Sheet A fő keresési szándékok
A1: A fő keresési szándékok és a hozzájuk javasolt kategória
A2: Nem a jelenlegi menü, hanem a keresési szándékok csoportosítása (Kulcsszótervező, HU, 12 hó átlag).
A4: Régi kategória | B4: Javaslat (hova kerüljön) | C4: Releváns keresés (Szoros+Laza)
A5: Főkategória-név | B5: A „légtechnika” (1300) a legerősebb általános szó; az „aktív szénszűrő” (210) a névadó termék. Javasolt menünév marad: „Aktív szénszűrő, légtechnika”; H1: „Légtechnika – aktív szénszűrő, csőventilátor, légtechnikai cső”. | C5: =SUMIFS(C16:C35,A16:A35,A5,E16:E35,"Igen")
A6: Elszívás | B6: → Csőventilátor, elszívó ventilátor | C6: =SUMIFS(C16:C35,A16:A35,A6,E16:E35,"Igen")
A7: Szagszűrés, szagkezelés | B7: → Aktív szénszűrő; Szagsemlegesítő | C7: =SUMIFS(C16:C35,A16:A35,A7,E16:E35,"Igen")
A8: Csövezés | B8: → Légtechnikai cső, idom, bilincs | C8: =SUMIFS(C16:C35,A16:A35,A8,E16:E35,"Igen")
A9: Légkeringetés | B9: → Keringető ventilátor | C9: =SUMIFS(C16:C35,A16:A35,A9,E16:E35,"Igen")
A10: Páratartalom | B10: → Páramentesítő; Párásító; Hő- és páratartalom-mérő | C10: =SUMIFS(C16:C35,A16:A35,A10,E16:E35,"Igen")
A11: Vezérlés | B11: → Klímavezérlő | C11: =SUMIFS(C16:C35,A16:A35,A11,E16:E35,"Igen")
A12: CO2 | B12: → CO2-pótlás, CO2-mérő | C12: =SUMIFS(C16:C35,A16:A35,A12,E16:E35,"Igen")
A15: Régi kategória | B15: Kulcsszó | C15: Havi keresés | D15: Kötődés a webshophoz | E15: Érdemes rá oldal? | F15: Javasolt felhasználás
A16: Főkategória-név | B16: légtechnika | C16: 1300 | D16: Szoros | E16: Igen | F16: Az új kategória leírásában / átirányítás (301) a régi URL-ről
A17: Főkategória-név | B17: légtechnikai bolt | C17: 720 | D17: Szoros | E17: Igen | F17: Az új kategória leírásában / átirányítás (301) a régi URL-ről
A18: Főkategória-név | B18: aktív szénszűrő | C18: 210 | D18: Szoros | E18: Igen | F18: Az új kategória leírásában / átirányítás (301) a régi URL-ről
A19: Főkategória-név | B19: légtechnika bolt | C19: 170 | D19: Szoros | E19: Igen | F19: Az új kategória leírásában / átirányítás (301) a régi URL-ről
A20: Főkategória-név | B20: légtechnika webáruház | C20: 110 | D20: Szoros | E20: Igen | F20: Az új kategória leírásában / átirányítás (301) a régi URL-ről
A21: Elszívás | B21: elszívó ventilátor | C21: 1900 | D21: Szoros | E21: Igen | F21: Az új kategória leírásában / átirányítás (301) a régi URL-ről
A22: Elszívás | B22: csőventilátor | C22: 1000 | D22: Szoros | E22: Igen | F22: Az új kategória leírásában / átirányítás (301) a régi URL-ről
A23: Szagszűrés, szagkezelés | B23: ózongenerátor | C23: 6600 | D23: Szoros | E23: Igen | F23: Az új kategória leírásában / átirányítás (301) a régi URL-ről
A24: Szagszűrés, szagkezelés | B24: szagsemlegesítő | C24: 260 | D24: Szoros | E24: Igen | F24: Az új kategória leírásában / átirányítás (301) a régi URL-ről
A25: Szagszűrés, szagkezelés | B25: aktív szénszűrő | C25: 210 | D25: Szoros | E25: Igen | F25: Az új kategória leírásában / átirányítás (301) a régi URL-ről
A26: Csövezés | B26: légtechnika cső | C26: 880 | D26: Szoros | E26: Igen | F26: Az új kategória leírásában / átirányítás (301) a régi URL-ről
A27: Csövezés | B27: légcsatorna | C27: 320 | D27: Szoros | E27: Igen | F27: Az új kategória leírásában / átirányítás (301) a régi URL-ről
... A35: CO2 | B35: co2 mérő | C35: 210 | D35: Szoros | E35: Igen | F35: Az új kategória leírásában / átirányítás (301) a régi URL-ről

Sheet Összes kulcsszó
A1: Kategória | B1: # | C1: Kulcsszó | D1: Megjegyzés (szint) | E1: Havi keresés | F1: Kötődés a webshophoz | G1: Érdemes rá kategória/oldal? | H1: Felhasználási terület | I1: Javasolt felhasználás
A2: Keringető ventilátor | B2: 2 | C2: ventilátor | E2: 18100 | F2: Laza | G2: Nem | H2: Légmozgatás a növények között – csíptetős (Monkey Fan, Cloudray), padló-, álló- és fali ventilátor | I2: Nem célozni külön oldallal (max. említés)
A3: Páramentesítő | B3: 1 | C3: páramentesítő | E3: 9900 | F3: Szoros | G3: Igen | H3: Páratartalom csökkentése a termesztőtérben, szárításnál – kompresszoros / Peltier páramentesítő | I3: Kategórianév + H1 + SEO title (fő kulcsszó)
A4: Szagsemlegesítő, ózongenerátor | B4: 2 | C4: ózongenerátor | E4: 6600 | F4: Szoros | G4: Igen | H4: Szagkezelés szénszűrő mellett / helyett – ONA gél, tömb, spray, légcsatornába építhető ONA szűrő, ózongenerátor | I4: SEO title / H1 / bevezető (másodlagos)
A5: Párásító | B5: 1 | C5: párásító | E5: 5400 | F5: Szoros | G5: Igen | H5: Páratartalom növelése a termesztőtérben – ultrahangos / hideg párásító, ködgenerátor, vezérlő | I5: Kategórianév + H1 + SEO title (fő kulcsszó)
A6: Keringető ventilátor | B6: 3 | C6: álló ventilátor | E6: 4400 | F6: Laza | G6: Nem | H6: Légmozgatás a növények között – csíptetős (Monkey Fan, Cloudray), padló-, álló- és fali ventilátor | I6: Nem célozni külön oldallal (max. említés)
A7: Párásító | B7: 2 | C7: párásító készülék | E7: 4400 | F7: Szoros | G7: Igen | H7: Páratartalom növelése a termesztőtérben – ultrahangos / hideg párásító, ködgenerátor, vezérlő | I7: SEO title / H1 / bevezető (másodlagos)
A8: Páramentesítő | B8: 2 | C8: párátlanító | E8: 3600 | F8: Szoros | G8: Igen | H8: Páratartalom csökkentése a termesztőtérben, szárításnál – kompresszoros / Peltier páramentesítő | I8: SEO title / H1 / bevezető (másodlagos)
A9: Légtechnikai cső, idom, bilincs | B9: 2 | C9: flexibilis cső | E9: 2400 | F9: Laza | G9: Nem | H9: Flexibilis légcsatorna (Aluflex, Sonoflex, Combiflex), idom, bővítő / szűkítő, csőtoldó, visszacsapó szelep, bilincs, ragasztószalag, ventilátor-hangtompító | I9: Nem célozni külön oldallal (max. említés)
A10: Légtechnikai cső, idom, bilincs | B10: 3 | C10: visszacsapó szelep | E10: 2400 | F10: Laza | G10: Nem | H10: Flexibilis légcsatorna (Aluflex, Sonoflex, Combiflex), idom, bővítő / szűkítő, csőtoldó, visszacsapó szelep, bilincs, ragasztószalag, ventilátor-hangtompító | I10: Nem célozni külön oldallal (max. említés)
A11: Keringető ventilátor | B11: 4 | C11: asztali ventilátor | E11: 2400 | F11: Laza | G11: Nem | H11: Légmozgatás a növények között – csíptetős (Monkey Fan, Cloudray), padló-, álló- és fali ventilátor | I11: Nem célozni külön oldallal (max. említés)
A12: Páramentesítő | B12: 3 | C12: páramentesítő gép | E12: 2400 | F12: Szoros | G12: Igen | H12: Páratartalom csökkentése a termesztőtérben, szárításnál – kompresszoros / Peltier páramentesítő | I12: SEO title / H1 / bevezető (másodlagos)
A13: Páramentesítő | B13: 4 | C13: páramentesítő készülék | E13: 2400 | F13: Szoros | G13: Igen | H13: Páratartalom csökkentése a termesztőtérben, szárításnál – kompresszoros / Peltier páramentesítő | I13: SEO title / H1 / bevezető (másodlagos)
... A198: CO2-pótlás, CO2-mérő | B198: 14 | C198: co2 tabletta | E198: 20 | F198: Szoros | G198: Igen | H198: CO2-szint emelése és mérése – CO2 zsák, tabletta, palack + reduktor, propános CO2 generátor, CO2 érzékelő / szabályzó | I198: Kategórialeírás (természetes említés)

Sheet 1 Csőventilátor
A1: Csőventilátor, elszívó ventilátor – fő kulcsszó: „csőventilátor”
A2: Felhasználási terület: Elszívás / befúvás a termesztőtérben – centrifugális, kevert áramlású és EC csőventilátor
A3: Megjegyzés: Az „elszívó ventilátor” (1900) nagyobb, de vegyes (fürdőszoba, konyha, ipar); a „csőventilátor” (1000) pontosabb – ez legyen a fő kulcsszó, az „elszívó ventilátor” a név második fele / H2. Átmérő szerinti szűrő érdemes (csőventilátor 100: 320, 150: 140, 125: 90). Fürdőszobai / WC / páraérzékelős elszívó nem a mi termékünk.
A4: Felvett releváns kulcsszavak: 36 (a Kulcsszótervező > 0 keresésű ötleteiből válogatva; a teljes nyers lista a CSV-ben)
A6: # | B6: Kulcsszó | C6: Havi keresés | D6: Kötődés a webshophoz | E6: Érdemes rá kategória/oldal? | F6: Felhasználási terület | G6: Javasolt felhasználás
A7: 1 | B7: csőventilátor | C7: 1000 | D7: Szoros | E7: Igen | F7: Elszívás / befúvás a termesztőtérben – centrifugális, kevert áramlású és EC csőventilátor | G7: Kategórianév + H1 + SEO title (fő kulcsszó)
A8: 2 | B8: elszívó ventilátor | C8: 1900 | D8: Szoros | E8: Igen | F8: Elszívás / befúvás a termesztőtérben – centrifugális, kevert áramlású és EC csőventilátor | G8: SEO title / H1 / bevezető (másodlagos)
A9: 3 | B9: elszívóventilátor | C9: 1900 | D9: Szoros | E9: Igen | F9: Elszívás / befúvás a termesztőtérben – centrifugális, kevert áramlású és EC csőventilátor | G9: Kategórialeírás (természetes említés)
A10: 4 | B10: páraérzékelős csőventilátor | C10: 480 | D10: Laza | E10: Nem | F10: Elszívás / befúvás a termesztőtérben – centrifugális, kevert áramlású és EC csőventilátor | G10: Nem célozni külön oldallal (max. említés)
A11: 5 | B11: fürdőszobai elszívó | C11: 390 | D11: Laza | E11: Nem | F11: Elszívás / befúvás a termesztőtérben – centrifugális, kevert áramlású és EC csőventilátor | G11: Nem célozni külön oldallal (max. említés)
A12: 6 | B12: csőventilátor 100 | C12: 320 | D12: Szoros | E12: Igen | F12: Elszívás / befúvás a termesztőtérben – centrifugális, kevert áramlású és EC csőventilátor | G12: SEO title / H1 / bevezető (másodlagos)
A13: 7 | B13: vents ventilátor | C13: 260 | D13: Szoros | E13: Igen | F13: Elszívás / befúvás a termesztőtérben – centrifugális, kevert áramlású és EC csőventilátor | G13: Gyártóoldal / szűrő / termékoldal
A14: 8 | B14: helios csőventilátor | C14: 260 | D14: Laza | E14: Nem | F14: Elszívás / befúvás a termesztőtérben – centrifugális, kevert áramlású és EC csőventilátor | G14: Nem célozni külön oldallal (max. említés)
A15: 9 | B15: wc elszívó ventilátor | C15: 260 | D15: Laza | E15: Nem | F15: Elszívás / befúvás a termesztőtérben – centrifugális, kevert áramlású és EC csőventilátor | G15: Nem célozni külön oldallal (max. említés)
A16: 10 | B16: csőventilátor praktiker | C16: 260 | D16: Nincs (áruházi / nem vásárlási szándék) | E16: Nem – kizárandó | F16: Elszívás / befúvás a termesztőtérben – centrifugális, kevert áramlású és EC csőventilátor | G16: Nem használni (áruházi/nem vásárlási szándék)
A17: 11 | B17: csőventilátorok | C17: 210 | D17: Szoros | E17: Igen | F17: Elszívás / befúvás a termesztőtérben – centrifugális, kevert áramlású és EC csőventilátor | G17: Kategórialeírás (természetes említés)
A18: 12 | B18: csoventillator | C18: 210 | D18: Szoros | E18: Igen | F18: Elszívás / befúvás a termesztőtérben – centrifugális, kevert áramlású és EC csőventilátor | G18: Kategórialeírás (természetes említés)
... A42: 36 | B42: ec ventilátor | C42: 20 | D42: Szoros | E42: Igen | F42: Elszívás / befúvás a termesztőtérben – centrifugális, kevert áramlású és EC csőventilátor | G42: Kategórialeírás (természetes említés)
B43: Összesen (érdemes rá oldal = Igen): | C43: =SUMIFS(C7:C42,E7:E42,"Igen")
A45: Termékek a jelenlegi kínálatból: 84 db (elsődleges + másodlagos hozzárendelés; egy termék több kategóriában is szerepelhet)
A46: # | B46: Termékkód | C46: Terméknév | D46: Hozzárendelés | E46: Illeszkedés | F46: Megjegyzés
A47: 1 | B47: GRO0346 | C47: Can-Fan RK 250 centrifugális csőventilátor 250 mm, 830 m3/h | D47: Elsődleges | E47: Erős | F47: Csőventilátor (Can-Fan, Vents, Prima Klima, AC Infinity, Garden Highpro, DF16)
A48: 2 | B48: GRO0776 | C48: Vents 100 VKO csőbe szerelhető axiális ventilátor 100 mm, 105 m3/h | D48: Elsődleges | E48: Erős | F48: Csőventilátor (Can-Fan, Vents, Prima Klima, AC Infinity, Garden Highpro, DF16)
A49: 3 | B49: GRO0777 | C49: Vents 125 VKO csőbe szerelhető axiális ventilátor 125 mm, 185 m3/h | D49: Elsődleges | E49: Erős | F49: Csőventilátor (Can-Fan, Vents, Prima Klima, AC Infinity, Garden Highpro, DF16)
A50: 4 | B50: GRO0778 | C50: Vents 150 VKO csőbe szerelhető axiális ventilátor 150 mm, 298 m3/h | D50: Elsődleges | E50: Erős | F50: Csőventilátor (Can-Fan, Vents, Prima Klima, AC Infinity, Garden Highpro, DF16)
A51: 5 | B51: GRO0779 | C51: Vents VK csatornaventilátor VK100 250m3 | D51: Elsődleges | E51: Erős | F51: Csőventilátor (Can-Fan, Vents, Prima Klima, AC Infinity, Garden Highpro, DF16)
A52: 6 | B52: GRO0780 | C52: Vents VK 125 centrifugális csatornaventilátor 125 mm | D52: Elsődleges | E52: Erős | F52: Csőventilátor (Can-Fan, Vents, Prima Klima, AC Infinity, Garden Highpro, DF16)
A53: 7 | B53: GRO0781 | C53: Vents VK 200 centrifugális csatornaventilátor 200 mm, 780 m3/h | D53: Elsődleges | E53: Erős | F53: Csőventilátor (Can-Fan, Vents, Prima Klima, AC Infinity, Garden Highpro, DF16)
A54: 8 | B54: GRO1108 | C54: Vents VK 150 centrifugális csatornaventilátor 150 mm, 460 m3/h | D54: Elsődleges | E54: Erős | F54: Csőventilátor (Can-Fan, Vents, Prima Klima, AC Infinity, Garden Highpro, DF16)
A55: 9 | B55: GRO1267 | C55: Can-Fan RK 160L centrifugális csőventilátor 160 mm, 780 m3/h | D55: Elsődleges | E55: Erős | F55: Csőventilátor (Can-Fan, Vents, Prima Klima, AC Infinity, Garden Highpro, DF16)
A56: 10 | B56: GRO1268 | C56: Can-Fan RK 200 centrifugális csőventilátor 200 mm, 820 m3/h | D56: Elsődleges | E56: Erős | F56: Csőventilátor (Can-Fan, Vents, Prima Klima, AC Infinity, Garden Highpro, DF16)
A57: 11 | B57: GRO1597 | C57: Can-Fan RK 100 centrifugális csőventilátor 100 mm, 240 m3/h | D57: Elsődleges | E57: Erős | F57: Csőventilátor (Can-Fan, Vents, Prima Klima, AC Infinity, Garden Highpro, DF16)
A58: 12 | B58: GRO1656 | C58: Can-Fan RK 125LS csőventilátor 125 mm, 370 m3/h, beépített 4 fokozatú kapcsolóval | D58: Elsődleges | E58: Erős | F58: Csőventilátor (Can-Fan, Vents, Prima Klima, AC Infinity, Garden Highpro, DF16)
... A130: 84 | B130: GRO4303 | C130: AC Infinity PRO légszűrő rendszer AI+WiFi 150 mm | D130: Másodlagos | E130: Erős | F130: AC Infinity légszűrő rendszer (ventilátor + szénszűrő)

Sheet 2 Szénszűrő
A1: Aktív szénszűrő, előszűrő – fő kulcsszó: „aktív szénszűrő”
A2: Felhasználási terület: Szagszűrés a termesztőtérből elszívott levegőből – aktív szénszűrő, előszűrő, utántöltő szén
A3: Megjegyzés: Kis, de tiszta szándékú klaszter (aktív szénszűrő 210, szénszűrő 170, aktívszén szűrő 140). A „szénszűrős páraelszívó” (480) és a „szagelszívó szénszűrő” (140) konyhai páraelszívó – nem a mi termékünk (LN). Growshop-specifikus kifejezés (pl. „szénszűrő csőventilátorhoz”) 20 alatt.
A4: Felvett releváns kulcsszavak: 14 (a Kulcsszótervező > 0 keresésű ötleteiből válogatva; a teljes nyers lista a CSV-ben)
A6: # | B6: Kulcsszó | C6: Havi keresés | D6: Kötődés a webshophoz | E6: Érdemes rá kategória/oldal? | F6: Felhasználási terület | G6: Javasolt felhasználás
A7: 1 | B7: aktív szénszűrő | C7: 210 | D7: Szoros | E7: Igen | F7: Szagszűrés a termesztőtérből elszívott levegőből – aktív szénszűrő, előszűrő, utántöltő szén | G7: Kategórianév + H1 + SEO title (fő kulcsszó)
A8: 2 | B8: szénszűrős páraelszívó kivezetés nélkül | C8: 480 | D8: Laza | E8: Nem | F8: Szagszűrés a termesztőtérből elszívott levegőből – aktív szénszűrő, előszűrő, utántöltő szén | G8: Nem célozni külön oldallal (max. említés)
A9: 3 | B9: szénszűrős páraelszívó | C9: 390 | D9: Laza | E9: Nem | F9: Szagszűrés a termesztőtérből elszívott levegőből – aktív szénszűrő, előszűrő, utántöltő szén | G9: Nem célozni külön oldallal (max. említés)
A10: 4 | B10: szénszűrő | C10: 170 | D10: Szoros | E10: Igen | F10: Szagszűrés a termesztőtérből elszívott levegőből – aktív szénszűrő, előszűrő, utántöltő szén | G10: SEO title / H1 / bevezető (másodlagos)
A11: 5 | B11: páraelszívó szénszűrő | C11: 170 | D11: Laza | E11: Nem | F11: Szagszűrés a termesztőtérből elszívott levegőből – aktív szénszűrő, előszűrő, utántöltő szén | G11: Nem célozni külön oldallal (max. említés)
A12: 6 | B12: aktívszén szűrő | C12: 140 | D12: Szoros | E12: Igen | F12: Szagszűrés a termesztőtérből elszívott levegőből – aktív szénszűrő, előszűrő, utántöltő szén | G12: SEO title / H1 / bevezető (másodlagos)
A13: 7 | B13: aktív szén szűrőbetét | C13: 140 | D13: Laza | E13: Igen | F13: Szagszűrés a termesztőtérből elszívott levegőből – aktív szénszűrő, előszűrő, utántöltő szén | G13: Kategórialeírás (természetes említés)
A14: 8 | B14: aktívszén szűrőbetét | C14: 140 | D14: Laza | E14: Igen | F14: Szagszűrés a termesztőtérből elszívott levegőből – aktív szénszűrő, előszűrő, utántöltő szén | G14: Kategórialeírás (természetes említés)
A15: 9 | B15: szagelszívó szűrő | C15: 140 | D15: Laza | E15: Nem | F15: Szagszűrés a termesztőtérből elszívott levegőből – aktív szénszűrő, előszűrő, utántöltő szén | G15: Nem célozni külön oldallal (max. említés)
A16: 10 | B16: szagelszívó szénszűrő | C16: 140 | D16: Laza | E16: Nem | F16: Szagszűrés a termesztőtérből elszívott levegőből – aktív szénszűrő, előszűrő, utántöltő szén | G16: Nem célozni külön oldallal (max. említés)
A17: 11 | B17: aktív szenes szűrő | C17: 70 | D17: Szoros | E17: Igen | F17: Szagszűrés a termesztőtérből elszívott levegőből – aktív szénszűrő, előszűrő, utántöltő szén | G17: Kategórialeírás (természetes említés)
A18: 12 | B18: aktív szén szűrő filter | C18: 50 | D18: Szoros | E18: Igen | F18: Szagszűrés a termesztőtérből elszívott levegőből – aktív szénszűrő, előszűrő, utántöltő szén | G18: Kategórialeírás (természetes említés)
... A20: 14 | B20: aktívszenes légtisztító | C20: 30 | D20: Laza | E20: Igen | F20: Szagszűrés a termesztőtérből elszívott levegőből – aktív szénszűrő, előszűrő, utántöltő szén | G20: Kategórialeírás (természetes említés)
B21: Összesen (érdemes rá oldal = Igen): | C21: =SUMIFS(C7:C20,E7:E20,"Igen")
A23: Termékek a jelenlegi kínálatból: 64 db (elsődleges + másodlagos hozzárendelés; egy termék több kategóriában is szerepelhet)
A24: # | B24: Termékkód | C24: Terméknév | D24: Hozzárendelés | E24: Illeszkedés | F24: Megjegyzés
A25: 1 | B25: GRO1044 | C25: Can Filters Can-Lite 1500 aktív szénszűrő acél házzal, 1500 m3/h, 250 mm szűrővég | D25: Elsődleges | E25: Erős | F25: Aktív szénszűrő (Can-Lite, Can Original, Can-Inline, Prima Klima, DF16, AC Infinity…)
A26: 2 | B26: GRO1075 | C26: Can Filters Can-Lite 2500 aktív szénszűrő acél házzal, 2500 m3/h, 250 mm szűrővég | D26: Elsődleges | E26: Erős | F26: Aktív szénszűrő (Can-Lite, Can Original, Can-Inline, Prima Klima, DF16, AC Infinity…)
A27: 3 | B27: GRO1077 | C27: Can Filters Can-Lite 1000 aktív szénszűrő acél házzal, 1000 m3/h, 250 mm szűrővég | D27: Elsődleges | E27: Erős | F27: Aktív szénszűrő (Can-Lite, Can Original, Can-Inline, Prima Klima, DF16, AC Infinity…)
A28: 4 | B28: GRO1078 | C28: Can Filters Can-Lite 600 aktív szénszűrő acél házzal, 600 m3/h, 150 mm szűrővég | D28: Elsődleges | E28: Erős | F28: Aktív szénszűrő (Can-Lite, Can Original, Can-Inline, Prima Klima, DF16, AC Infinity…)
A29: 5 | B29: GRO1079 | C29: Can Filters Can-Lite 300 aktív szénszűrő műanyag házzal, 300 m3/h | D29: Elsődleges | E29: Erős | F29: Aktív szénszűrő (Can-Lite, Can Original, Can-Inline, Prima Klima, DF16, AC Infinity…)
A30: 6 | B30: GRO1080 | C30: Can Filters Can-Lite 150 aktív szénszűrő műanyag házzal, 150 m3/h | D30: Elsődleges | E30: Erős | F30: Aktív szénszűrő (Can-Lite, Can Original, Can-Inline, Prima Klima, DF16, AC Infinity…)
A31: 7 | B31: GRO1081 | C31: Can Filters Can-Lite 425 aktív szénszűrő műanyag házzal, 425 m3/h | D31: Elsődleges | E31: Erős | F31: Aktív szénszűrő (Can-Lite, Can Original, Can-Inline, Prima Klima, DF16, AC Infinity…)
A32: 8 | B32: GRO1663 | C32: Can Filters Can-Lite 3000 aktív szénszűrő acél házzal, 3000 m3/h, 315 mm szűrővég | D32: Elsődleges | E32: Erős | F32: Aktív szénszűrő (Can-Lite, Can Original, Can-Inline, Prima Klima, DF16, AC Infinity…)
A33: 9 | B33: GRO2182 | C33: Can Filters Can-Lite műanyag szűrővég 100 mm, Can-Lite 150, 300 és 425 szénszűrőhöz | D33: Elsődleges | E33: Erős | F33: Aktív szénszűrő (Can-Lite, Can Original, Can-Inline, Prima Klima, DF16, AC Infinity…)
A34: 10 | B34: GRO2220 | C34: Can Filters Can-Lite műanyag szűrővég 125 mm, Can-Lite 150, 300 és 425 szénszűrőhöz | D34: Elsődleges | E34: Erős | F34: Aktív szénszűrő (Can-Lite, Can Original, Can-Inline, Prima Klima, DF16, AC Infinity…)
A35: 11 | B35: GRO2921 | C35: Can Filters Can-Lite 800 aktív szénszűrő acél házzal, 800 m3/h, 200 mm szűrővég | D35: Elsődleges | E35: Erős | F35: Aktív szénszűrő (Can-Lite, Can Original, Can-Inline, Prima Klima, DF16, AC Infinity…)
A36: 12 | B36: GRO3211 | C36: CAN Original aktív szénszűrő CF 2100 m3/h, 250 mm szűrővég, pelletált szénnel | D36: Elsődleges | E36: Erős | F36: Előszűrő, utántöltő szénpellet
... A88: 64 | B88: GRO4342 | C88: AC Infinity szénszűrő Australian Charcoal d: 200 mm 1308 m3/h | D88: Elsődleges | E88: Erős | F88: Aktív szénszűrő (Can-Lite, Can Original, Can-Inline, Prima Klima, DF16, AC Infinity…)

Sheet 3 Légtechnikai cső
A1: Légtechnikai cső, idom, bilincs – fő kulcsszó: „légtechnika cső”
A2: Felhasználási terület: Flexibilis légcsatorna (Aluflex, Sonoflex, Combiflex), idom, bővítő / szűkítő, csőtoldó, visszacsapó szelep, bilincs, ragasztószalag, ventilátor-hangtompító
A3: Megjegyzés: A keresők „légtechnika csövet” keresnek (880), nem légcsatornát (320); légtechnikai idom 210, légtechnika idomok 210. A „flexibilis cső” (2400), „visszacsapó szelep” (2400) és „hangtompító” (880) jórészt vízvezeték / autó – LN.
A4: Felvett releváns kulcsszavak: 31 (a Kulcsszótervező > 0 keresésű ötleteiből válogatva; a teljes nyers lista a CSV-ben)
A6: # | B6: Kulcsszó | C6: Havi keresés | D6: Kötődés a webshophoz | E6: Érdemes rá kategória/oldal? | F6: Felhasználási terület | G6: Javasolt felhasználás
A7: 1 | B7: légtechnika cső | C7: 880 | D7: Szoros | E7: Igen | F7: Flexibilis légcsatorna (Aluflex, Sonoflex, Combiflex), idom, bővítő / szűkítő, csőtoldó, visszacsapó szelep, bilincs, ragasztószalag, ventilátor-hangtompító | G7: Kategórianév + H1 + SEO title (fő kulcsszó)
A8: 2 | B8: flexibilis cső | C8: 2400 | D8: Laza | E8: Nem | F8: Flexibilis légcsatorna (Aluflex, Sonoflex, Combiflex), idom, bővítő / szűkítő, csőtoldó, visszacsapó szelep, bilincs, ragasztószalag, ventilátor-hangtompító | G8: Nem célozni külön oldallal (max. említés)
A9: 3 | B9: visszacsapó szelep | C9: 2400 | D9: Laza | E9: Nem | F9: Flexibilis légcsatorna (Aluflex, Sonoflex, Combiflex), idom, bővítő / szűkítő, csőtoldó, visszacsapó szelep, bilincs, ragasztószalag, ventilátor-hangtompító | G9: Nem célozni külön oldallal (max. említés)
A10: 4 | B10: csőbilincs | C10: 1900 | D10: Laza | E10: Nem | F10: Flexibilis légcsatorna (Aluflex, Sonoflex, Combiflex), idom, bővítő / szűkítő, csőtoldó, visszacsapó szelep, bilincs, ragasztószalag, ventilátor-hangtompító | G10: Nem célozni külön oldallal (max. említés)
A11: 5 | B11: duct tape | C11: 1600 | D11: Laza | E11: Igen | F11: Flexibilis légcsatorna (Aluflex, Sonoflex, Combiflex), idom, bővítő / szűkítő, csőtoldó, visszacsapó szelep, bilincs, ragasztószalag, ventilátor-hangtompító | G11: Kategórialeírás (természetes említés)
A12: 6 | B12: hangtompító | C12: 880 | D12: Laza | E12: Nem | F12: Flexibilis légcsatorna (Aluflex, Sonoflex, Combiflex), idom, bővítő / szűkítő, csőtoldó, visszacsapó szelep, bilincs, ragasztószalag, ventilátor-hangtompító | G12: Nem célozni külön oldallal (max. említés)
A13: 7 | B13: alumínium ragasztószalag | C13: 720 | D13: Szoros | E13: Igen | F13: Flexibilis légcsatorna (Aluflex, Sonoflex, Combiflex), idom, bővítő / szűkítő, csőtoldó, visszacsapó szelep, bilincs, ragasztószalag, ventilátor-hangtompító | G13: SEO title / H1 / bevezető (másodlagos)
A14: 8 | B14: alu ragasztószalag | C14: 720 | D14: Szoros | E14: Igen | F14: Flexibilis légcsatorna (Aluflex, Sonoflex, Combiflex), idom, bővítő / szűkítő, csőtoldó, visszacsapó szelep, bilincs, ragasztószalag, ventilátor-hangtompító | G14: Kategórialeírás (természetes említés)
A15: 9 | B15: szellőző cső | C15: 390 | D15: Szoros | E15: Igen | F15: Flexibilis légcsatorna (Aluflex, Sonoflex, Combiflex), idom, bővítő / szűkítő, csőtoldó, visszacsapó szelep, bilincs, ragasztószalag, ventilátor-hangtompító | G15: SEO title / H1 / bevezető (másodlagos)
A16: 10 | B16: légcsatorna | C16: 320 | D16: Szoros | E16: Igen | F16: Flexibilis légcsatorna (Aluflex, Sonoflex, Combiflex), idom, bővítő / szűkítő, csőtoldó, visszacsapó szelep, bilincs, ragasztószalag, ventilátor-hangtompító | G16: SEO title / H1 / bevezető (másodlagos)
A17: 11 | B17: légtechnikai idom | C17: 210 | D17: Szoros | E17: Igen | F17: Flexibilis légcsatorna (Aluflex, Sonoflex, Combiflex), idom, bővítő / szűkítő, csőtoldó, visszacsapó szelep, bilincs, ragasztószalag, ventilátor-hangtompító | G17: SEO title / H1 / bevezető (másodlagos)
A18: 12 | B18: légtechnika idomok | C18: 210 | D18: Szoros | E18: Igen | F18: Flexibilis légcsatorna (Aluflex, Sonoflex, Combiflex), idom, bővítő / szűkítő, csőtoldó, visszacsapó szelep, bilincs, ragasztószalag, ventilátor-hangtompító | G18: SEO title / H1 / bevezető (másodlagos)
... A37: 31 | B37: légtechnikai bilincs | C37: 20 | D37: Szoros | E37: Igen | F37: Flexibilis légcsatorna (Aluflex, Sonoflex, Combiflex), idom, bővítő / szűkítő, csőtoldó, visszacsapó szelep, bilincs, ragasztószalag, ventilátor-hangtompító | G37: Kategórialeírás (természetes említés)
B38: Összesen (érdemes rá oldal = Igen): | C38: =SUMIFS(C7:C37,E7:E37,"Igen")
A40: Termékek a jelenlegi kínálatból: 114 db (elsődleges + másodlagos hozzárendelés; egy termék több kategóriában is szerepelhet)
A41: # | B41: Termékkód | C41: Terméknév | D41: Hozzárendelés | E41: Illeszkedés | F41: Megjegyzés
A42: 1 | B42: GRO0306 | C42: Flexibilis alumínium légcsatorna cső Aluflex 102 mm, 10 m | D42: Elsődleges | E42: Erős | F42: Flexibilis légcsatorna cső (Aluflex, Sonoflex, Combiflex)
A43: 2 | B43: GRO0307 | C43: Flexibilis alumínium légcsatorna cső Aluflex 127 mm, 10 m | D43: Elsődleges | E43: Erős | F43: Flexibilis légcsatorna cső (Aluflex, Sonoflex, Combiflex)
A44: 3 | B44: GRO0308 | C44: Flexibilis alumínium légcsatorna cső Aluflex 152 mm, 10 m | D44: Elsődleges | E44: Erős | F44: Flexibilis légcsatorna cső (Aluflex, Sonoflex, Combiflex)
A45: 4 | B45: GRO0310 | C45: Flexibilis alumínium légcsatorna cső Aluflex 203 mm, 10 m | D45: Elsődleges | E45: Erős | F45: Flexibilis légcsatorna cső (Aluflex, Sonoflex, Combiflex)
A46: 5 | B46: GRO0312 | C46: Flexibilis alumínium légcsatorna cső Aluflex 315 mm, 10 m | D46: Elsődleges | E46: Erős | F46: Flexibilis légcsatorna cső (Aluflex, Sonoflex, Combiflex)
A47: 6 | B47: GRO0317 | C47: Sonoflex hang- és hőszigetelt flexibilis légcsatorna cső 102 mm, 10 m | D47: Elsődleges | E47: Erős | F47: Flexibilis légcsatorna cső (Aluflex, Sonoflex, Combiflex)
A48: 7 | B48: GRO0318 | C48: Sonoflex hang- és hőszigetelt flexibilis légcsatorna cső 127 mm, 10 m | D48: Elsődleges | E48: Erős | F48: Flexibilis légcsatorna cső (Aluflex, Sonoflex, Combiflex)
A49: 8 | B49: GRO0319 | C49: Sonoflex hang- és hőszigetelt flexibilis légcsatorna cső 152 mm, 10 m | D49: Elsődleges | E49: Erős | F49: Flexibilis légcsatorna cső (Aluflex, Sonoflex, Combiflex)
A50: 9 | B50: GRO0321 | C50: Sonoflex hang- és hőszigetelt flexibilis légcsatorna cső 203 mm, 10 m | D50: Elsődleges | E50: Erős | F50: Flexibilis légcsatorna cső (Aluflex, Sonoflex, Combiflex)
A51: 10 | B51: GRO0322 | C51: Sonoflex hang- és hőszigetelt flexibilis légcsatorna cső 254 mm, 10 m | D51: Elsődleges | E51: Erős | F51: Flexibilis légcsatorna cső (Aluflex, Sonoflex, Combiflex)
A52: 11 | B52: GRO0330 | C52: Combiflex 6 rétegű flexibilis alumínium légcsatorna cső 102 mm, 10 m | D52: Elsődleges | E52: Erős | F52: Flexibilis légcsatorna cső (Aluflex, Sonoflex, Combiflex)
A53: 12 | B53: GRO0331 | C53: Combiflex 6 rétegű flexibilis alumínium légcsatorna cső 127 mm, 10 m | D53: Elsődleges | E53: Erős | F53: Flexibilis légcsatorna cső (Aluflex, Sonoflex, Combiflex)
... A155: 114 | B155: GRO2653 | C155: ONA Air Filter beépíthető szagtalanító ONA Block tömbökhöz, 315 mm-es légcsatornába | D155: Másodlagos | E155: Erős | F155: ONA Air Filter – légcsatornába építhető

Sheet 4 Szagsemlegesítő
A1: Szagsemlegesítő, ózongenerátor – fő kulcsszó: „szagsemlegesítő”
A2: Felhasználási terület: Szagkezelés szénszűrő mellett / helyett – ONA gél, tömb, spray, légcsatornába építhető ONA szűrő, ózongenerátor
A3: Megjegyzés: Az „ózongenerátor” (6600) a legnagyobb szó az egész ágban, de csak 1 ózongenerátor termékünk van – a fő kulcsszó a „szagsemlegesítő” (260) legyen, az ózongenerátor H2 / szűrő. Ha bővül az ózongenerátor-kínálat, külön 3. szintű kategóriát érdemel. A „szagtalanító spray” (390) jó az ONA spray-re.
A4: Felvett releváns kulcsszavak: 30 (a Kulcsszótervező > 0 keresésű ötleteiből válogatva; a teljes nyers lista a CSV-ben)
A6: # | B6: Kulcsszó | C6: Havi keresés | D6: Kötődés a webshophoz | E6: Érdemes rá kategória/oldal? | F6: Felhasználási terület | G6: Javasolt felhasználás
A7: 1 | B7: szagsemlegesítő | C7: 260 | D7: Szoros | E7: Igen | F7: Szagkezelés szénszűrő mellett / helyett – ONA gél, tömb, spray, légcsatornába építhető ONA szűrő, ózongenerátor | G7: Kategórianév + H1 + SEO title (fő kulcsszó)
A8: 2 | B8: ózongenerátor | C8: 6600 | D8: Szoros | E8: Igen | F8: Szagkezelés szénszűrő mellett / helyett – ONA gél, tömb, spray, légcsatornába építhető ONA szűrő, ózongenerátor | G8: SEO title / H1 / bevezető (másodlagos)
A9: 3 | B9: ozon generátor | C9: 1000 | D9: Szoros | E9: Igen | F9: Szagkezelés szénszűrő mellett / helyett – ONA gél, tömb, spray, légcsatornába építhető ONA szűrő, ózongenerátor | G9: Kategórialeírás (természetes említés)
A10: 4 | B10: ózon generator | C10: 1000 | D10: Szoros | E10: Igen | F10: Szagkezelés szénszűrő mellett / helyett – ONA gél, tömb, spray, légcsatornába építhető ONA szűrő, ózongenerátor | G10: Kategórialeírás (természetes említés)
A11: 5 | B11: ózóngenerátor | C11: 720 | D11: Szoros | E11: Igen | F11: Szagkezelés szénszűrő mellett / helyett – ONA gél, tömb, spray, légcsatornába építhető ONA szűrő, ózongenerátor | G11: Kategórialeírás (természetes említés)
A12: 6 | B12: ózongenerátor használata | C12: 720 | D12: Szoros | E12: Igen | F12: Szagkezelés szénszűrő mellett / helyett – ONA gél, tömb, spray, légcsatornába építhető ONA szűrő, ózongenerátor | G12: Leírás alsó része, GYIK vagy blog
A13: 7 | B13: ózongenerátor fertőtlenítés | C13: 590 | D13: Laza | E13: Igen | F13: Szagkezelés szénszűrő mellett / helyett – ONA gél, tömb, spray, légcsatornába építhető ONA szűrő, ózongenerátor | G13: Kategórialeírás (természetes említés)
A14: 8 | B14: ózongenerátor ár | C14: 480 | D14: Szoros | E14: Igen | F14: Szagkezelés szénszűrő mellett / helyett – ONA gél, tömb, spray, légcsatornába építhető ONA szűrő, ózongenerátor | G14: Kategórialeírás (természetes említés)
A15: 9 | B15: szagtalanító spray | C15: 390 | D15: Szoros | E15: Igen | F15: Szagkezelés szénszűrő mellett / helyett – ONA gél, tömb, spray, légcsatornába építhető ONA szűrő, ózongenerátor | G15: SEO title / H1 / bevezető (másodlagos)
A16: 10 | B16: ózón generátor | C16: 390 | D16: Szoros | E16: Igen | F16: Szagkezelés szénszűrő mellett / helyett – ONA gél, tömb, spray, légcsatornába építhető ONA szűrő, ózongenerátor | G16: Kategórialeírás (természetes említés)
A17: 11 | B17: ózongenerátor mire jó | C17: 390 | D17: Szoros | E17: Igen | F17: Szagkezelés szénszűrő mellett / helyett – ONA gél, tömb, spray, légcsatornába építhető ONA szűrő, ózongenerátor | G17: Leírás alsó része, GYIK vagy blog
A18: 12 | B18: ózongenerátor tisztítás | C18: 320 | D18: Laza | E18: Igen | F18: Szagkezelés szénszűrő mellett / helyett – ONA gél, tömb, spray, légcsatornába építhető ONA szűrő, ózongenerátor | G18: Leírás alsó része, GYIK vagy blog
... A36: 30 | B36: ona gel | C36: 20 | D36: Szoros | E36: Igen | F36: Szagkezelés szénszűrő mellett / helyett – ONA gél, tömb, spray, légcsatornába építhető ONA szűrő, ózongenerátor | G36: Gyártóoldal / szűrő / termékoldal
B37: Összesen (érdemes rá oldal = Igen): | C37: =SUMIFS(C7:C36,E7:E36,"Igen")
A39: Termékek a jelenlegi kínálatból: 49 db (elsődleges + másodlagos hozzárendelés; egy termék több kategóriában is szerepelhet)
A40: # | B40: Termékkód | C40: Terméknév | D40: Hozzárendelés | E40: Illeszkedés | F40: Megjegyzés
A41: 1 | B41: GRO0797 | C41: Ozonizátor, ózongenerátor szagtalanításhoz 200 mg/h, 7 W, időzítővel | D41: Elsődleges | E41: Erős | F41: Ózongenerátor
A42: 2 | B42: GRO2472 | C42: ONA Block szagsemlegesítő tömb Pro illat, 170 g, kis helyekre és légcsatornába | D42: Elsődleges | E42: Erős | F42: ONA gél, tömb, spray, folyadék
A43: 3 | B43: GRO2473 | C43: ONA Block szagsemlegesítő tömb Polar Crystal illat, 170 g, kis helyekre és légcsatornába | D43: Elsődleges | E43: Erős | F43: ONA gél, tömb, spray, folyadék
A44: 4 | B44: GRO2474 | C44: ONA Block szagsemlegesítő tömb Fresh Linen illat, 170 g, kis helyekre és légcsatornába | D44: Elsődleges | E44: Erős | F44: ONA gél, tömb, spray, folyadék
A45: 5 | B45: GRO2475 | C45: ONA Gel szagsemlegesítő zselé Pro illat, 500 ml (400 g) | D45: Elsődleges | E45: Erős | F45: ONA gél, tömb, spray, folyadék
A46: 6 | B46: GRO2476 | C46: ONA Gel szagsemlegesítő zselé (Pro) 1 liter | D46: Elsődleges | E46: Erős | F46: ONA gél, tömb, spray, folyadék
A47: 7 | B47: GRO2477 | C47: ONA Gel szagsemlegesítő zselé (Pro) 4 liter | D47: Elsődleges | E47: Erős | F47: ONA gél, tömb, spray, folyadék
A48: 8 | B48: GRO2478 | C48: ONA Gel szagsemlegesítő zselé Polar Crystal illat, 500 ml (400 g) | D48: Elsődleges | E48: Erős | F48: ONA gél, tömb, spray, folyadék
A49: 9 | B49: GRO2479 | C49: ONA Gel szagsemlegesítő zselé Polar Crystal illat, 1 liter (732 g) | D49: Elsődleges | E49: Erős | F49: ONA gél, tömb, spray, folyadék
A50: 10 | B50: GRO2480 | C50: ONA Gel szagsemlegesítő zselé (Polar Crystal) 4 liter | D50: Elsődleges | E50: Erős | F50: ONA gél, tömb, spray, folyadék
A51: 11 | B51: GRO2481 | C51: ONA Gel szagsemlegesítő zselé Fresh Linen illat, 500 ml (400 g) | D51: Elsődleges | E51: Erős | F51: ONA gél, tömb, spray, folyadék
A52: 12 | B52: GRO2483 | C52: ONA Gel szagsemlegesítő zselé Fresh Linen illat, 4 liter (3,8 kg) | D52: Elsődleges | E52: Erős | F52: ONA gél, tömb, spray, folyadék
... A89: 49 | B89: GRO3939 | C89: ONA Gel szagsemlegesítő zselé (Lemongrass) 1 liter | D89: Elsődleges | E89: Erős | F89: ONA gél, tömb, spray, folyadék

Sheet 5 Keringető
A1: Keringető ventilátor – fő kulcsszó: „padlóventilátor”
A2: Felhasználási terület: Légmozgatás a növények között – csíptetős (Monkey Fan, Cloudray), padló-, álló- és fali ventilátor
A3: Megjegyzés: A „keringető ventilátor” és a „csíptetős ventilátor” 20 alatti. A forgalmat a háztartási típusszavak hozzák (padlóventilátor 1300, fali ventilátor 880, ipari ventilátor 1000) – ezek laza kötődésűek, de ugyanaz a termékkör. A „ventilátor” (18100) és az „álló ventilátor” (4400) túl általános (LN).
A4: Felvett releváns kulcsszavak: 14 (a Kulcsszótervező > 0 keresésű ötleteiből válogatva; a teljes nyers lista a CSV-ben)
A6: # | B6: Kulcsszó | C6: Havi keresés | D6: Kötődés a webshophoz | E6: Érdemes rá kategória/oldal? | F6: Felhasználási terület | G6: Javasolt felhasználás
A7: 1 | B7: padlóventilátor | C7: 1300 | D7: Szoros | E7: Igen | F7: Légmozgatás a növények között – csíptetős (Monkey Fan, Cloudray), padló-, álló- és fali ventilátor | G7: Kategórianév + H1 + SEO title (fő kulcsszó)
A8: 2 | B8: ventilátor | C8: 18100 | D8: Laza | E8: Nem | F8: Légmozgatás a növények között – csíptetős (Monkey Fan, Cloudray), padló-, álló- és fali ventilátor | G8: Nem célozni külön oldallal (max. említés)
A9: 3 | B9: álló ventilátor | C9: 4400 | D9: Laza | E9: Nem | F9: Légmozgatás a növények között – csíptetős (Monkey Fan, Cloudray), padló-, álló- és fali ventilátor | G9: Nem célozni külön oldallal (max. említés)
A10: 4 | B10: asztali ventilátor | C10: 2400 | D10: Laza | E10: Nem | F10: Légmozgatás a növények között – csíptetős (Monkey Fan, Cloudray), padló-, álló- és fali ventilátor | G10: Nem célozni külön oldallal (max. említés)
A11: 5 | B11: padló ventilátor | C11: 1300 | D11: Szoros | E11: Igen | F11: Légmozgatás a növények között – csíptetős (Monkey Fan, Cloudray), padló-, álló- és fali ventilátor | G11: SEO title / H1 / bevezető (másodlagos)
A12: 6 | B12: szellőztető ventilátor | C12: 1300 | D12: Laza | E12: Igen | F12: Légmozgatás a növények között – csíptetős (Monkey Fan, Cloudray), padló-, álló- és fali ventilátor | G12: Kategórialeírás (természetes említés)
A13: 7 | B13: ipari ventilátor | C13: 1000 | D13: Laza | E13: Igen | F13: Légmozgatás a növények között – csíptetős (Monkey Fan, Cloudray), padló-, álló- és fali ventilátor | G13: SEO title / H1 / bevezető (másodlagos)
A14: 8 | B14: fali ventilátor | C14: 880 | D14: Laza | E14: Igen | F14: Légmozgatás a növények között – csíptetős (Monkey Fan, Cloudray), padló-, álló- és fali ventilátor | G14: SEO title / H1 / bevezető (másodlagos)
A15: 9 | B15: nagy teljesítményű ventilátor | C15: 390 | D15: Laza | E15: Igen | F15: Légmozgatás a növények között – csíptetős (Monkey Fan, Cloudray), padló-, álló- és fali ventilátor | G15: Kategórialeírás (természetes említés)
